Workbook
Name THZM4AB_pollen: HOL_LitTransp!$B$1:$CO$86
Name THZM4AB_pollen: HoloceneLitt2009!$B$1:$CO$87
Name THZM4AB_pollen: LittLittStacked!$B$3:$CO$87
Name THZM4AB_pollen: LittLittStackedPer!$B$3:$CO$87
Name THZM4AB_pollen_1: LittLittStackedPer!$B$3:$CO$87

Sheet UsigerLittStacked
C1: ABIES | D1: ACER | E1: ALISMATACE | F1: ALNUS | G1: ANDERE_ERI | H1: ANEMONE_TY | I1: ARCTOST_ | J1: ARMERIA | K1: ARTEMISIA | L1: BATRACHIUM | M1: BETULA | N1: BORAGINACE | O1: BOTRYCHIUM | P1: BUXUS | Q1: CALLUNA | R1: CALTHA_TYP | S1: CAMPANULAC | T1: CANNABIS | U1: CARDUUS_T_ | V1: CARPINUS | W1: CARYOPHYLL | X1: CENTAUREA | Y1: CENTAUREA2 | Z1: CENTAUREA3 | AA1: CENTAUREA_ | AB1: CEREALIA | AC1: CHAMAENERI | AD1: CHENOPODIA | AE1: ASTEROIDAE | AF1: CICHORIOIDEAE | AG1: CORYLUS | AH1: BRASSICAC_ | AI1: CYPERACEAE | AJ1: DIPSACACEA | AK1: ECHIUM | AL1: EMPETRUM | AM1: EPHEDRA | AN1: EPHEDRA_DI | AO1: EPHEDRA_FR | AP1: EPILOBIUM | AQ1: EQUISETUM | AR1: ERICA | AS1: EUONYMUS | AT1: EUONYMUS_V | AU1: FAGOPYRUM_ | AV1: FAGUS | AW1: FILICOPSIDA | AX1: FILIPENDUL | AY1: FILIPENDULA_T | AZ1: FRAXINUS | BA1: RUBIACEAE | BB1: GENTIANACE | BC1: GERANIUM | BD1: GYPSOPHILA | BE1: HEDERA | BF1: HELIANTHEM | BG1: HIPPOPHAEA | BH1: HUMULUS_TY | BI1: HYPERICUM | BJ1: ILEX | BK1: JUGLANS | BL1: JUNIPERUS | BM1: LAMIACEAE | BN1: LEGUMINOSEA | BO1: LIGULIFLOR | BP1: LILIACEAE | BQ1: LINUM | BR1: LITORELLA | BS1: LYC_CLAVAT | BT1: LYSIMACHIA | BU1: LYTHRUM | BV1: MELAMPYRUM | BW1: MENTHA | BX1: MENYANTHES | BY1: MERCURIALI | BZ1: MYRICA | CA1: MYRIOPHYLL | CB1: MYRIOPHYL2 | CC1: NUPHAR | CD1: NYMPHAEA | CE1: OPHIOGLOSS | CF1: FABACEAE | CG1: PARNASSIA | CH1: PEDIASTRUM | CI1: PICEA | CJ1: PINUS | CK1: PLANTAGO_L | CL1: PLANTAGO_M | CM1: PLANTAGO_2 | CN1: POLEMONIU2 | CO1: POLEMONIUM | CP1: POLYGONUM2 | CQ1: POLYGONUM_ | CR1: POLYGONUM4 | CS1: POLYGONUM3 | CT1: POLYPODIAC | CU1: POLYPODIUM | CV1: POPULUS | CW1: POTAMOGETO | CX1: POTENTILLA | CY1: PTERIDIUM | CZ1: QUERCUS | DA1: RANUNCULAC | DB1: RHAMNUS_CA | DC1: RHAMNUS_FR | DD1: RHEUM | DE1: ROSACEAE | DF1: RUMEX | DG1: SAGITTARIA | DH1: SALIX | DI1: SAMBUCUS | DJ1: SANGUISORB | DK1: SANGUISOR2 | DL1: SANGUISORBA_2 | DM1: SAROTHAMNU | DN1: SAXIFRAGA | DO1: SAXIFRAGA_ | DP1: SCROPHULARIA | DQ1: SECALE | DR1: SELAGINELLA | DS1: SOLANACEAE | DT1: SORBUS | DU1: SPARGANIUM | DV1: SPHAGNUM | DW1: SUCCISA | DX1: TAXUS | DY1: THALICTRUM | DZ1: TILIA | EA1: TRIFOLIUM_ | EB1: TUBULIFLOR | EC1: TYPHA_LATI | ED1: ULMUS | EE1: APIACEAE | EF1: URTICA | EG1: VACCINIUM | EH1: VALERIANA | EI1: VALERIANA_ | EJ1: VALERIANA2 | EK1: VIBURNUM | EL1: VICIA | EM1: VISCUM | EN1: POACEAE
B2: Type | C2: =LOOKUP(C4,[1]env!$A:$A,[1]env!$B:$B) -> Arboreal | D2: =LOOKUP(D4,[1]env!$A:$A,[1]env!$B:$B) -> Arboreal | E2: =LOOKUP(E4,[1]env!$A:$A,[1]env!$B:$B) -> Aquatic | F2: =LOOKUP(F4,[1]env!$A:$A,[1]env!$B:$B) -> Arboreal | G2: Herb | H2: Herb | I2: Herb | J2: Herb | K2: =LOOKUP(K4,[1]env!$A:$A,[1]env!$B:$B) -> Herb | L2: Aquatic | M2: =LOOKUP(M4,[1]env!$A:$A,[1]env!$B:$B) -> Arboreal | N2: Herb | O2: Herb | P2: =LOOKUP(P4,[1]env!$A:$A,[1]env!$B:$B) -> Arboreal | Q2: =LOOKUP(Q4,[1]env!$A:$A,[1]env!$B:$B) -> Herb | R2: Herb | S2: =LOOKUP(S4,[1]env!$A:$A,[1]env!$B:$B) -> Herb | T2: =LOOKUP(T4,[1]env!$A:$A,[1]env!$B:$B) -> Herb | U2: Herb | V2: =LOOKUP(V4,[1]env!$A:$A,[1]env!$B:$B) -> Arboreal | W2: =LOOKUP(W4,[1]env!$A:$A,[1]env!$B:$B) -> Herb | X2: =LOOKUP(X4,[1]env!$A:$A,[1]env!$B:$B) -> Herb | Y2: =LOOKUP(Y4,[1]env!$A:$A,[1]env!$B:$B) -> Herb | Z2: =LOOKUP(Z4,[1]env!$A:$A,[1]env!$B:$B) -> Herb | AA2: =LOOKUP(AA4,[1]env!$A:$A,[1]env!$B:$B) -> Herb | AB2: Herb | AC2: =LOOKUP(AC4,[1]env!$A:$A,[1]env!$B:$B) -> Herb | AD2: =LOOKUP(AD4,[1]env!$A:$A,[1]env!$B:$B) -> Herb | AE2: =LOOKUP(AE4,[1]env!$A:$A,[1]env!$B:$B) -> Herb | AF2: Herb | AG2: =LOOKUP(AG4,[1]env!$A:$A,[1]env!$B:$B) -> Arboreal | AH2: =LOOKUP(AH4,[1]env!$A:$A,[1]env!$B:$B) -> Herb | AI2: =LOOKUP(AI4,[1]env!$A:$A,[1]env!$B:$B) -> Herb | AJ2: =LOOKUP(AJ4,[1]env!$A:$A,[1]env!$B:$B) -> Herb | AK2: =LOOKUP(AK4,[1]env!$A:$A,[1]env!$B:$B) -> Herb | AL2: Herb | AM2: Shrub | AN2: Shrub | AO2: Shrub | AP2: =LOOKUP(AP4,[1]env!$A:$A,[1]env!$B:$B) -> Herb | AQ2: =LOOKUP(AQ4,[1]env!$A:$A,[1]env!$B:$B) -> Aquatic | AR2: Herb | AS2: Arboreal | AT2: =LOOKUP(AT4,[1]env!$A:$A,[1]env!$B:$B) -> Arboreal | AU2: =LOOKUP(AU4,[1]env!$A:$A,[1]env!$B:$B) -> Herb | AV2: =LOOKUP(AV4,[1]env!$A:$A,[1]env!$B:$B) -> Arboreal | AW2: Aquatic | AX2: =LOOKUP(AX4,[1]env!$A:$A,[1]env!$B:$B) -> Herb | AY2: =LOOKUP(AY4,[1]env!$A:$A,[1]env!$B:$B) -> Herb | AZ2: =LOOKUP(AZ4,[1]env!$A:$A,[1]env!$B:$B) -> Arboreal | BA2: Herb | BB2: =LOOKUP(BB4,[1]env!$A:$A,[1]env!$B:$B) -> Herb | BC2: =LOOKUP(BC4,[1]env!$A:$A,[1]env!$B:$B) -> Herb | BD2: Herb | BE2: =LOOKUP(BE4,[1]env!$A:$A,[1]env!$B:$B) -> Herb | BF2: =LOOKUP(BF4,[1]env!$A:$A,[1]env!$B:$B) -> Herb | BG2: =LOOKUP(BG4,[1]env!$A:$A,[1]env!$B:$B) -> Arboreal | BH2: Herb | BI2: Herb | BJ2: Arboreal | BK2: =LOOKUP(BK4,[1]env!$A:$A,[1]env!$B:$B) -> Arboreal | BL2: =LOOKUP(BL4,[1]env!$A:$A,[1]env!$B:$B) -> Arboreal | BM2: =LOOKUP(BM4,[1]env!$A:$A,[1]env!$B:$B) -> Herb | BN2: =LOOKUP(BN4,[1]env!$A:$A,[1]env!$B:$B) -> Herb | BO2: Herb | BP2: =LOOKUP(BP4,[1]env!$A:$A,[1]env!$B:$B) -> Herb | BQ2: =LOOKUP(BQ4,[1]env!$A:$A,[1]env!$B:$B) -> Herb | BR2: Aquatic | BS2: Herb | BT2: Herb | BU2: Herb | BV2: Herb | BW2: =LOOKUP(BW4,[1]env!$A:$A,[1]env!$B:$B) -> Herb | BX2: Aquatic | BY2: Herb | BZ2: Arboreal | CA2: Aquatic | CB2: =LOOKUP(CB4,[1]env!$A:$A,[1]env!$B:$B) -> Aquatic | CC2: =LOOKUP(CC4,[1]env!$A:$A,[1]env!$B:$B) -> Aquatic | CD2: =LOOKUP(CD4,[1]env!$A:$A,[1]env!$B:$B) -> Aquatic | CE2: Fern | CF2: Shrub | CG2: Herb | CH2: =LOOKUP(CH4,[1]env!$A:$A,[1]env!$B:$B) -> Aquatic | CI2: =LOOKUP(CI4,[1]env!$A:$A,[1]env!$B:$B) -> Arboreal | CJ2: =LOOKUP(CJ4,[1]env!$A:$A,[1]env!$B:$B) -> Arboreal | CK2: =LOOKUP(CK4,[1]env!$A:$A,[1]env!$B:$B) -> Herb | CL2: =LOOKUP(CL4,[1]env!$A:$A,[1]env!$B:$B) -> Herb | CM2: =LOOKUP(CM4,[1]env!$A:$A,[1]env!$B:$B) -> Herb | CN2: =LOOKUP(CN4,[1]env!$A:$A,[1]env!$B:$B) -> Herb | CO2: =LOOKUP(CO4,[1]env!$A:$A,[1]env!$B:$B) -> Herb | ... CS2: =LOOKUP(CS4,[1]env!$A:$A,[1]env!$B:$B) -> Herb | CT2: Fern | CU2: Fern | CV2: =LOOKUP(CV4,[1]env!$A:$A,[1]env!$B:$B) -> Arboreal | CW2: =LOOKUP(CW4,[1]env!$A:$A,[1]env!$B:$B) -> Aquatic | CX2: Herb | CY2: Herb | CZ2: =LOOKUP(CZ4,[1]env!$A:$A,[1]env!$B:$B) -> Arboreal | DA2: =LOOKUP(DA4,[1]env!$A:$A,[1]env!$B:$B) -> Herb | DB2: Arboreal | DC2: =LOOKUP(DC4,[1]env!$A:$A,[1]env!$B:$B) -> Arboreal | DD2: Herb | DE2: =LOOKUP(DE4,[1]env!$A:$A,[1]env!$B:$B) -> Herb | DF2: Herb | DG2: Aquatic | DH2: =LOOKUP(DH4,[1]env!$A:$A,[1]env!$B:$B) -> Arboreal | DI2: =LOOKUP(DI4,[1]env!$A:$A,[1]env!$B:$B) -> Arboreal | DJ2: =LOOKUP(DJ4,[1]env!$A:$A,[1]env!$B:$B) -> Herb | DK2: =LOOKUP(DK4,[1]env!$A:$A,[1]env!$B:$B) -> Herb | DL2: =LOOKUP(DL4,[1]env!$A:$A,[1]env!$B:$B) -> Herb | DM2: Shrub | DN2: =LOOKUP(DN4,[1]env!$A:$A,[1]env!$B:$B) -> Herb | DO2: =LOOKUP(DO4,[1]env!$A:$A,[1]env!$B:$B) -> Herb | DP2: Herb | DQ2: =LOOKUP(DQ4,[1]env!$A:$A,[1]env!$B:$B) -> Herb | DR2: Moss | DS2: =LOOKUP(DS4,[1]env!$A:$A,[1]env!$B:$B) -> Herb | DT2: Arboreal | DU2: Aquatic | DV2: =LOOKUP(DV4,[1]env!$A:$A,[1]env!$B:$B) -> Aquatic | DW2: =LOOKUP(DW4,[1]env!$A:$A,[1]env!$B:$B) -> Herb | DX2: =LOOKUP(DX4,[1]env!$A:$A,[1]env!$B:$B) -> Arboreal | DY2: Herb | DZ2: =LOOKUP(DZ4,[1]env!$A:$A,[1]env!$B:$B) -> Arboreal | EA2: Herb | EB2: Herb | EC2: =LOOKUP(EC4,[1]env!$A:$A,[1]env!$B:$B) -> Aquatic | ED2: =LOOKUP(ED4,[1]env!$A:$A,[1]env!$B:$B) -> Arboreal | EE2: =LOOKUP(EE4,[1]env!$A:$A,[1]env!$B:$B) -> Herb | EF2: =LOOKUP(EF4,[1]env!$A:$A,[1]env!$B:$B) -> Herb | EG2: Herb | EH2: =LOOKUP(EH4,[1]env!$A:$A,[1]env!$B:$B) -> Herb | EI2: Herb | EJ2: Herb | EK2: Shrub | EL2: Herb | EM2: Herb | EN2: Herb
B3: Cat | C3: A | D3: A | E3: W | F3: A | G3: H | H3: H | I3: H | J3: H | K3: H | L3: W | M3: A | N3: H | O3: H | P3: A | Q3: H | R3: H | S3: H | T3: H | U3: H | V3: A | W3: H | X3: H | Y3: H | Z3: H | AA3: H | AB3: H | AC3: H | AD3: H | AE3: H | AF3: H | AG3: A | AH3: H | AI3: H | AJ3: H | AK3: H | AL3: H | AM3: A | AN3: A | AO3: A | AP3: H | AQ3: W | AR3: H | AS3: A | AT3: A | AU3: H | AV3: A | AW3: W | AX3: H | AY3: H | AZ3: A | BA3: H | BB3: H | BC3: H | BD3: H | BE3: H | BF3: H | BG3: A | BH3: H | BI3: H | BJ3: A | BK3: A | BL3: A | BM3: H | BN3: H | BO3: H | BP3: H | BQ3: H | BR3: W | BS3: H | BT3: H | BU3: H | BV3: H | BW3: H | BX3: W | BY3: H | BZ3: A | CA3: W | CB3: W | CC3: W | CD3: W | CE3: F | CF3: A | CG3: H | CH3: W | CI3: A | CJ3: A | CK3: H | CL3: H | CM3: H | CN3: H | CO3: H | CP3: H | CQ3: H | CR3: H | CS3: H | CT3: F | CU3: F | CV3: A | CW3: W | CX3: H | CY3: H | CZ3: A | DA3: H | DB3: A | DC3: A | DD3: H | DE3: H | DF3: H | DG3: W | DH3: A | DI3: A | DJ3: H | DK3: H | DL3: H | DM3: A | DN3: H | DO3: H | DP3: H | DQ3: H | DR3: F | DS3: H | DT3: A | DU3: W | DV3: W | DW3: H | DX3: A | DY3: H | DZ3: A | EA3: H | EB3: H | EC3: W | ED3: A | EE3: H | EF3: H | EG3: H | EH3: H | EI3: H | EJ3: H | EK3: A | EL3: H | EM3: H | EN3: H
A4: Depth (cm) | B4: Age | C4: Abies | D4: Acer | E4: Alisma | F4: Alnus | G4: Andere Erical.indet. | H4: Anemome Typ | I4: Arctost. | J4: Armeria | K4: Artemisia | L4: Batrachium | M4: Betula | N4: Boraginaceae | O4: Botrychium | P4: Buxus | Q4: Calluna | R4: Caltha | S4: Campanulaceae | T4: Cannabis | U4: Carduus T. | V4: Carpinus | W4: Caryophyllaceae | X4: Centaurea | Y4: Centaurea cyanus | Z4: Centaurea jacea | AA4: Centaurea scabiosa | AB4: Cerealia | AC4: Chamaenerion-T. | AD4: Chenopodiaceae | AE4: Compositae Subfam. Asteroideae | AF4: Compositae Subfam. Cichorioideae | AG4: Corylus | AH4: Cruciferae | AI4: Cyperaceae | AJ4: Dipsacaceae | AK4: Echium | AL4: Empetrum | AM4: Ephedra | AN4: Ephedra dist. | AO4: Ephedra frag. | AP4: Epilobium | AQ4: Equisetum | AR4: Erica | AS4: Euonymus | AT4: Euonymus/Viburnum | AU4: Fagopyrum esculentum | AV4: Fagus | AW4: Filicopsida monolete undiff. | AX4: Filipendula | AY4: Filipendula-type | AZ4: Fraxinus | BA4: Galium type | BB4: Gentianaceae | BC4: Geranium | BD4: Gypsophila | BE4: Hedera | BF4: Helianthemum | BG4: Hippophaea | BH4: Humulus-Typ | BI4: Hypericum | BJ4: Ilex | BK4: Juglans | BL4: Juniperus | BM4: Labiatae dreifaltig | BN4: Leguminosae | BO4: Liguliflorae | BP4: Liliaceae | BQ4: Linum | BR4: Litorella | BS4: Lyc.clavatum | BT4: Lysimachia | BU4: Lythrum | BV4: Melampyrum | BW4: Mentha | BX4: Menyanthes | BY4: Mercurialis annua | BZ4: Myrica | CA4: Myriophyllum altern. | CB4: Myriophyllum spicat. | CC4: Nuphar | CD4: Nymphaea | CE4: Ophioglossum | CF4: Papilionaceae | CG4: Parnassia | CH4: Pediastrum | CI4: Picea | CJ4: Pinus | CK4: Plantago lanceolata | CL4: Plantago major | CM4: Plantago maritima | CN4: Polemonium | CO4: Polemonium | CP4: Polygonum amphibium | CQ4: Polygonum aviculare | CR4: Polygonum bistorta | CS4: Polygonum persicaria | CT4: Polypodiaceae | CU4: Polypodium vulgare | CV4: Populus | CW4: Potamogeton-Typ | CX4: Potentilla | CY4: Pteridium | CZ4: Quercus | DA4: Ranunculaceae | DB4: Rhamnus cathatica | DC4: Rhamnus frangula | DD4: Rheum | DE4: Rosaceae | DF4: Rumex | DG4: Sagittaria | DH4: Salix | DI4: Sambucus | DJ4: Sanguisorba minor | DK4: Sanguisorba off. | DL4: Sanguisorba officinalis | DM4: Sarothamnus | DN4: Saxifraga | DO4: Saxifraga opp. | DP4: Scrophulariaceae | DQ4: Secale | DR4: Selaginella selaginoides | DS4: Solanaceae | DT4: Sorbus | DU4: Sparganium | DV4: Sphagnum | DW4: Succisa | DX4: Taxus | DY4: Thalictrum | DZ4: Tilia | EA4: Trifolium T. | EB4: Tubuliflorae psilat | EC4: Typha latifolium | ED4: Ulmus | EE4: Umbelliferae | EF4: Urtica | EG4: Vaccinium | EH4: Valeriana | EI4: Valeriana dioica | EJ4: Valeriana officinal. | EK4: Viburnum | EL4: Vicia-type | EM4: Viscum | EN4: Wildgramineae
A5: 1 | B5: -40 | C5: 1.5 | D5: 0 | E5: 0 | F5: 15 | G5: 0 | H5: 0 | I5: 0 | J5: 0 | K5: 0 | L5: 39 | M5: 33 | N5: 0 | O5: 0 | P5: 0 | Q5: 2 | R5: 0 | S5: 1 | T5: 1 | U5: 0 | V5: 18 | W5: 1 | X5: 0 | Y5: 0 | Z5: 0 | AA5: 0 | AB5: 25 | AC5: 0 | AD5: 6 | AG5: 18 | AH5: 2 | AI5: 37 | AJ5: 0 | AK5: 0 | AL5: 0 | AM5: 0 | AN5: 0 | AO5: 0 | AP5: 0 | AQ5: 0 | AR5: 0 | AS5: 0 | AT5: 0 | AU5: 0 | AV5: 53 | AX5: 4 | AZ5: 8 | BA5: 1 | BB5: 0 | BC5: 0 | BD5: 0 | BE5: 0 | BF5: 0 | BG5: 0 | BH5: 3 | BI5: 0 | BJ5: 0 | BK5: 0 | BL5: 5 | BM5: 0 | BO5: 5 | BP5: 0 | BQ5: 0 | BR5: 2 | BS5: 0 | BT5: 0 | BU5: 1 | BV5: 0 | BW5: 1 | BX5: 0 | BY5: 3 | BZ5: 0 | CA5: 3 | CB5: 1 | CC5: 0 | CD5: 0 | CE5: 0 | CF5: 0 | CG5: 0 | CH5: 93 | CI5: 20 | CJ5: 69 | CK5: 14 | CL5: 1 | CM5: 0 | CN5: 0 | CO5: 0 | CP5: 1 | CQ5: 1 | CS5: 0 | CT5: 7 | CU5: 0 | CV5: 1 | CW5: 8 | CX5: 0 | CY5: 2 | CZ5: 54 | DA5: 5 | DB5: 0 | DC5: 0 | DD5: 0 | DE5: 3 | DF5: 27 | DG5: 0 | DH5: 6 | DI5: 2 | DJ5: 1 | DK5: 0 | DM5: 0 | DN5: 0 | DO5: 0 | DQ5: 16 | DS5: 1 | DT5: 0 | DU5: 0 | DV5: 0 | DX5: 0 | DY5: 0 | DZ5: 0 | EA5: 0 | EB5: 12 | EC5: 0 | ED5: 3 | EE5: 0 | EF5: 34 | EG5: 0 | EH5: 0 | EI5: 0 | EJ5: 0 | EK5: 0 | EM5: 0 | EN5: 210
A6: 3 | B6: -39 | C6: 0 | D6: 0 | E6: 0 | F6: 35 | G6: 0 | H6: 0 | I6: 0 | J6: 0 | K6: 1 | L6: 37 | M6: 39 | N6: 0 | O6: 0 | P6: 0 | Q6: 2 | R6: 0 | S6: 0 | T6: 0 | U6: 0 | V6: 25 | W6: 0 | X6: 0 | Y6: 0 | Z6: 0 | AA6: 0 | AB6: 23 | AC6: 0 | AD6: 4 | AG6: 21 | AH6: 2 | AI6: 35 | AJ6: 0 | AK6: 0 | AL6: 0 | AM6: 0 | AN6: 0 | AO6: 0 | AP6: 0 | AQ6: 2 | AR6: 0 | AS6: 0 | AT6: 0 | AU6: 0 | AV6: 63 | AX6: 4 | AZ6: 13 | BA6: 1 | BB6: 0 | BC6: 0 | BD6: 0 | BE6: 0 | BF6: 0 | BG6: 0 | BH6: 1 | BI6: 0 | BJ6: 0 | BK6: 1 | BL6: 7 | BM6: 0 | BO6: 10 | BP6: 0 | BQ6: 0 | BR6: 2 | BS6: 0 | BT6: 0 | BU6: 0 | BV6: 0 | BW6: 0 | BX6: 0 | BY6: 4 | BZ6: 0 | CA6: 3 | CB6: 4 | CC6: 0 | CD6: 0 | CE6: 0 | CF6: 5 | CG6: 0 | CH6: 129 | CI6: 23 | CJ6: 73 | CK6: 21 | CL6: 4 | CM6: 0 | CN6: 0 | CO6: 0 | CP6: 0 | CQ6: 0 | CS6: 0 | CT6: 5 | CU6: 0 | CV6: 0 | CW6: 8 | CX6: 0 | CY6: 0 | CZ6: 59 | DA6: 13 | DB6: 0 | DC6: 0 | DD6: 0 | DE6: 4 | DF6: 30 | DG6: 0 | DH6: 8 | DI6: 2 | DJ6: 1 | DK6: 0 | DM6: 0 | DN6: 0 | DO6: 0 | DQ6: 24 | DS6: 0 | DT6: 0 | DU6: 1 | DV6: 0 | DX6: 0 | DY6: 0 | DZ6: 0 | EA6: 0 | EB6: 0 | EC6: 0 | ED6: 1 | EE6: 1 | EF6: 50 | EG6: 0 | EH6: 0 | EI6: 0 | EJ6: 0 | EK6: 0 | EM6: 0 | EN6: 258
A7: 5 | B7: -18 | C7: 0 | D7: 0 | E7: 0 | F7: 13 | G7: 0 | H7: 0 | I7: 0 | J7: 0 | K7: 2 | L7: 40 | M7: 39 | N7: 0 | O7: 0 | P7: 0 | Q7: 2 | R7: 0 | S7: 0 | T7: 1 | U7: 0 | V7: 13 | W7: 1 | X7: 0 | Y7: 0 | Z7: 0 | AA7: 0 | AB7: 27 | AC7: 0 | AD7: 4 | AG7: 17 | AH7: 4 | AI7: 33 | AJ7: 0 | AK7: 0 | AL7: 0 | AM7: 0 | AN7: 0 | AO7: 0 | AP7: 0 | AQ7: 0 | AR7: 0 | AS7: 0 | AT7: 0 | AU7: 0 | AV7: 81 | AX7: 1 | AZ7: 15 | BA7: 1 | BB7: 0 | BC7: 0 | BD7: 0 | BE7: 0 | BF7: 0 | BG7: 0 | BH7: 0 | BI7: 0 | BJ7: 0 | BK7: 0 | BL7: 11 | BM7: 0 | BO7: 4 | BP7: 0 | BQ7: 0 | BR7: 1 | BS7: 0 | BT7: 0 | BU7: 0 | BV7: 0 | BW7: 1 | BX7: 0 | BY7: 8 | BZ7: 0 | CA7: 9 | CB7: 6 | CC7: 0 | CD7: 0 | CE7: 0 | CF7: 0 | CG7: 0 | CH7: 131 | CI7: 125 | CJ7: 54.5 | CK7: 17 | CL7: 4 | CM7: 0 | CN7: 0 | CO7: 0 | CP7: 0 | CQ7: 2 | CS7: 0 | CT7: 5 | CU7: 0 | CV7: 4 | CW7: 8 | CX7: 0 | CY7: 0 | CZ7: 69 | DA7: 10 | DB7: 0 | DC7: 0 | DD7: 0 | DE7: 2 | DF7: 40 | DG7: 0 | DH7: 6 | DI7: 2 | DJ7: 0 | DK7: 0 | DM7: 0 | DN7: 0 | DO7: 0 | DQ7: 27 | DS7: 1 | DT7: 0 | DU7: 0 | DV7: 0 | DX7: 0 | DY7: 0 | DZ7: 1 | EA7: 0 | EB7: 5 | EC7: 0 | ED7: 4 | EE7: 3 | EF7: 36 | EG7: 0 | EH7: 0 | EI7: 0 | EJ7: 0 | EK7: 0 | EM7: 0 | EN7: 229
A8: 7 | B8: 3 | C8: 0 | D8: 0 | E8: 0 | F8: 24 | G8: 0 | H8: 0 | I8: 0 | J8: 0 | K8: 1 | L8: 23 | M8: 44 | N8: 0 | O8: 0 | P8: 1 | Q8: 2 | R8: 0 | S8: 0 | T8: 0 | U8: 0 | V8: 20 | W8: 0 | X8: 0 | Y8: 0 | Z8: 0 | AA8: 0 | AB8: 31 | AC8: 0 | AD8: 4 | AG8: 33 | AH8: 4 | AI8: 36 | AJ8: 0 | AK8: 0 | AL8: 0 | AM8: 0 | AN8: 0 | AO8: 0 | AP8: 0 | AQ8: 0 | AR8: 0 | AS8: 0 | AT8: 0 | AU8: 0 | AV8: 75 | AX8: 2 | AZ8: 11 | BA8: 0 | BB8: 0 | BC8: 0 | BD8: 0 | BE8: 0 | BF8: 0 | BG8: 0 | BH8: 0 | BI8: 0 | BJ8: 0 | BK8: 0 | BL8: 6 | BM8: 0 | BO8: 5 | BP8: 0 | BQ8: 0 | BR8: 2 | BS8: 0 | BT8: 0 | BU8: 0 | BV8: 0 | BW8: 1 | BX8: 0 | BY8: 6 | BZ8: 0 | CA8: 1 | CB8: 6 | CC8: 0 | CD8: 1 | CE8: 0 | CF8: 1 | CG8: 0 | CH8: 121 | CI8: 21 | CJ8: 65.5 | CK8: 11 | CL8: 2 | CM8: 0 | CN8: 0 | CO8: 0 | CP8: 1 | CQ8: 1 | CS8: 0 | CT8: 6 | CU8: 0 | CV8: 2 | CW8: 15 | CX8: 0 | CY8: 1 | CZ8: 68 | DA8: 9 | DB8: 0 | DC8: 0 | DD8: 0 | DE8: 2 | DF8: 19 | DG8: 0 | DH8: 18 | DI8: 3 | DJ8: 0 | DK8: 0 | DM8: 0 | DN8: 0 | DO8: 0 | DQ8: 23 | DS8: 0 | DT8: 0 | DU8: 1 | DV8: 0 | DX8: 0 | DY8: 0 | DZ8: 0 | EA8: 0 | EB8: 8 | EC8: 0 | ED8: 0 | EE8: 3 | EF8: 42 | EG8: 0 | EH8: 0 | EI8: 0 | EJ8: 0 | EK8: 0 | EM8: 0 | EN8: 305
A9: 10 | B9: 34 | C9: 0 | D9: 0 | E9: 0 | F9: 19 | G9: 0 | H9: 0 | I9: 0 | J9: 0 | K9: 1 | L9: 40 | M9: 46 | N9: 0 | O9: 0 | P9: 0 | Q9: 2 | R9: 0 | S9: 1 | T9: 1 | U9: 0 | V9: 21 | W9: 3 | X9: 0 | Y9: 0 | Z9: 0 | AA9: 0 | AB9: 20 | AC9: 0 | AD9: 4 | AG9: 18 | AH9: 5 | AI9: 42 | AJ9: 0 | AK9: 1 | AL9: 0 | AM9: 0 | AN9: 0 | AO9: 0 | AP9: 0 | AQ9: 0 | AR9: 0 | AS9: 0 | AT9: 0 | AU9: 0 | AV9: 73 | AX9: 4 | AZ9: 15 | BA9: 4 | BB9: 0 | BC9: 0 | BD9: 0 | BE9: 1 | BF9: 0 | BG9: 0 | BH9: 2 | BI9: 0 | BJ9: 0 | BK9: 1 | BL9: 14 | BM9: 0 | BO9: 8 | BP9: 0 | BQ9: 0 | BR9: 0 | BS9: 0 | BT9: 0 | BU9: 0 | BV9: 0 | BW9: 0 | BX9: 0 | BY9: 5 | BZ9: 0 | CA9: 1 | CB9: 4 | CC9: 0 | CD9: 0 | CE9: 0 | CF9: 3 | CG9: 0 | CH9: 145 | CI9: 20 | CJ9: 46 | CK9: 26 | CL9: 4 | CM9: 0 | CN9: 0 | CO9: 0 | CP9: 0 | CQ9: 0 | CS9: 0 | CT9: 5 | CU9: 0 | CV9: 6 | CW9: 13 | CX9: 0 | CY9: 4 | CZ9: 70 | DA9: 7 | DB9: 0 | DC9: 0 | DD9: 0 | DE9: 1 | DF9: 40 | DG9: 0 | DH9: 10 | DI9: 0 | DJ9: 1 | DK9: 0 | DM9: 0 | DN9: 0 | DO9: 0 | DQ9: 20 | DS9: 0 | DT9: 0 | DU9: 0 | DV9: 0 | DX9: 0 | DY9: 0 | DZ9: 0 | EA9: 0 | EB9: 4 | EC9: 0 | ED9: 4 | EE9: 2 | EF9: 27 | EG9: 0 | EH9: 0 | EI9: 0 | EJ9: 0 | EK9: 0 | EM9: 0 | EN9: 236
A10: 14 | B10: 71 | C10: 0 | D10: 0 | E10: 0 | F10: 15 | G10: 0 | H10: 0 | I10: 0 | J10: 0 | K10: 1 | L10: 26 | M10: 30 | N10: 0 | O10: 0 | P10: 0 | Q10: 0 | R10: 0 | S10: 1 | T10: 2 | U10: 0 | V10: 8 | W10: 0 | X10: 0 | Y10: 0 | Z10: 0 | AA10: 0 | AB10: 16 | AC10: 0 | AD10: 0 | AG10: 13 | AH10: 1 | AI10: 24 | AJ10: 0 | AK10: 0 | AL10: 0 | AM10: 0 | AN10: 0 | AO10: 0 | AP10: 0 | AQ10: 1 | AR10: 0 | AS10: 0 | AT10: 0 | AU10: 0 | AV10: 62 | AX10: 0 | AZ10: 7 | BA10: 1 | BB10: 0 | BC10: 0 | BD10: 0 | BE10: 0 | BF10: 0 | BG10: 0 | BH10: 0 | BI10: 0 | BJ10: 0 | BK10: 0 | BL10: 7 | BM10: 0 | BO10: 5 | BP10: 0 | BQ10: 0 | BR10: 0 | BS10: 0 | BT10: 0 | BU10: 1 | BV10: 0 | BW10: 0 | BX10: 0 | BY10: 3 | BZ10: 0 | CA10: 0 | CB10: 7 | CC10: 0 | CD10: 0 | CE10: 0 | CF10: 0 | CG10: 0 | CH10: 120 | CI10: 17 | CJ10: 42.5 | CK10: 10 | CL10: 2 | CM10: 0 | CN10: 0 | CO10: 0 | CP10: 0 | CQ10: 1 | CS10: 1 | CT10: 7 | CU10: 0 | CV10: 2 | CW10: 5 | CX10: 0 | CY10: 0 | CZ10: 49 | DA10: 5 | DB10: 0 | DC10: 0 | DD10: 0 | DE10: 4 | DF10: 31 | DG10: 0 | DH10: 5 | DI10: 4 | DJ10: 0 | DK10: 0 | DM10: 0 | DN10: 0 | DO10: 0 | DQ10: 12 | DS10: 0 | DT10: 0 | DU10: 0 | DV10: 0 | DX10: 0 | DY10: 0 | DZ10: 1 | EA10: 0 | EB10: 4 | EC10: 0 | ED10: 2 | EE10: 1 | EF10: 35 | EG10: 0 | EH10: 0 | EI10: 0 | EJ10: 0 | EK10: 0 | EM10: 0 | EN10: 185
A11: 18 | B11: 83 | C11: 0 | D11: 0 | E11: 0 | F11: 14 | G11: 0 | H11: 0 | I11: 0 | J11: 0 | K11: 0 | L11: 22 | M11: 35 | N11: 0 | O11: 0 | P11: 0 | Q11: 1 | R11: 0 | S11: 0 | T11: 3 | U11: 0 | V11: 21 | W11: 1 | X11: 0 | Y11: 0 | Z11: 0 | AA11: 0 | AB11: 19 | AC11: 0 | AD11: 3 | AG11: 18 | AH11: 1 | AI11: 25 | AJ11: 0 | AK11: 0 | AL11: 0 | AM11: 0 | AN11: 0 | AO11: 0 | AP11: 0 | AQ11: 0 | AR11: 0 | AS11: 0 | AT11: 0 | AU11: 0 | AV11: 46 | AX11: 1 | AZ11: 11 | BA11: 1 | BB11: 0 | BC11: 0 | BD11: 0 | BE11: 0 | BF11: 0 | BG11: 0 | BH11: 0 | BI11: 0 | BJ11: 0 | BK11: 0 | BL11: 3 | BM11: 0 | BO11: 7 | BP11: 0 | BQ11: 0 | BR11: 2 | BS11: 0 | BT11: 0 | BU11: 0 | BV11: 0 | BW11: 0 | BX11: 0 | BY11: 6 | BZ11: 0 | CA11: 1 | CB11: 3 | CC11: 0 | CD11: 0 | CE11: 0 | CF11: 4 | CG11: 0 | CH11: 111 | CI11: 10 | CJ11: 35 | CK11: 15 | CL11: 1 | CM11: 0 | CN11: 0 | CO11: 0 | CP11: 0 | CQ11: 1 | CS11: 0 | CT11: 1 | CU11: 0 | CV11: 2 | CW11: 4 | CX11: 0 | CY11: 1 | CZ11: 59 | DA11: 4 | DB11: 0 | DC11: 0 | DD11: 0 | DE11: 2 | DF11: 44 | DG11: 0 | DH11: 3 | DI11: 2 | DJ11: 2 | DK11: 0 | DM11: 0 | DN11: 0 | DO11: 0 | DQ11: 22 | DS11: 0 | DT11: 1 | DU11: 0 | DV11: 0 | DX11: 0 | DY11: 0 | DZ11: 0 | EA11: 0 | EB11: 3 | EC11: 0 | ED11: 2 | EE11: 2 | EF11: 32 | EG11: 0 | EH11: 0 | EI11: 0 | EJ11: 0 | EK11: 0 | EM11: 0 | EN11: 178
A12: 22 | B12: 94 | C12: 0 | D12: 0 | E12: 0 | F12: 18 | G12: 0 | H12: 0 | I12: 0 | J12: 0 | K12: 2 | L12: 42 | M12: 37 | N12: 0 | O12: 1 | P12: 0 | Q12: 5 | R12: 0 | S12: 0 | T12: 2 | U12: 0 | V12: 30 | W12: 0 | X12: 0 | Y12: 1 | Z12: 0 | AA12: 0 | AB12: 31 | AC12: 0 | AD12: 7 | AG12: 36 | AH12: 10 | AI12: 44 | AJ12: 0 | AK12: 0 | AL12: 0 | AM12: 0 | AN12: 0 | AO12: 0 | AP12: 0 | AQ12: 1 | AR12: 0 | AS12: 0 | AT12: 0 | AU12: 1 | AV12: 97 | AX12: 0 | AZ12: 22 | BA12: 3 | BB12: 0 | BC12: 0 | BD12: 0 | BE12: 0 | BF12: 0 | BG12: 0 | BH12: 0 | BI12: 0 | BJ12: 0 | BK12: 0 | BL12: 7 | BM12: 0 | BO12: 17 | BP12: 0 | BQ12: 0 | BR12: 2 | BS12: 0 | BT12: 0 | BU12: 0 | BV12: 0 | BW12: 0 | BX12: 0 | BY12: 8 | BZ12: 0 | CA12: 1 | CB12: 8 | CC12: 0 | CD12: 0 | CE12: 0 | CF12: 3 | CG12: 0 | CH12: 134 | CI12: 16 | CJ12: 43 | CK12: 32 | CL12: 5 | CM12: 0 | CN12: 0 | CO12: 0 | CP12: 0 | CQ12: 6 | CS12: 0 | CT12: 9 | CU12: 0 | CV12: 1 | CW12: 14 | CX12: 0 | CY12: 1 | CZ12: 66 | DA12: 10 | DB12: 0 | DC12: 1 | DD12: 0 | DE12: 1 | DF12: 49 | DG12: 0 | DH12: 6 | DI12: 0 | DJ12: 3 | DK12: 0 | DM12: 0 | DN12: 0 | DO12: 0 | DQ12: 36 | DS12: 0 | DT12: 0 | DU12: 0 | DV12: 1 | DX12: 1 | DY12: 0 | DZ12: 0 | EA12: 0 | EB12: 6 | EC12: 0 | ED12: 1 | EE12: 3 | EF12: 26 | EG12: 0 | EH12: 0 | EI12: 0 | EJ12: 0 | EK12: 0 | EM12: 0 | EN12: 269
A13: 26 | B13: 106 | C13: 0 | D13: 0 | E13: 0 | F13: 11 | G13: 0 | H13: 0 | I13: 0 | J13: 0 | K13: 1 | L13: 34 | M13: 22 | N13: 0 | O13: 0 | P13: 0 | Q13: 3 | R13: 0 | S13: 1 | T13: 0 | U13: 0 | V13: 19 | W13: 0 | X13: 0 | Y13: 0 | Z13: 0 | AA13: 0 | AB13: 15 | AC13: 0 | AD13: 3 | AG13: 17 | AH13: 7 | AI13: 20 | AJ13: 0 | AK13: 1 | AL13: 0 | AM13: 0 | AN13: 0 | AO13: 0 | AP13: 0 | AQ13: 0 | AR13: 0 | AS13: 0 | AT13: 0 | AU13: 0 | AV13: 81 | AX13: 3 | AZ13: 4 | BA13: 3 | BB13: 0 | BC13: 0 | BD13: 0 | BE13: 0 | BF13: 0 | BG13: 0 | BH13: 0 | BI13: 0 | BJ13: 0 | BK13: 0 | BL13: 2 | BM13: 0 | BO13: 13 | BP13: 0 | BQ13: 0 | BR13: 1 | BS13: 0 | BT13: 0 | BU13: 0 | BV13: 0 | BW13: 0 | BX13: 0 | BY13: 3 | BZ13: 0 | CA13: 0 | CB13: 2 | CC13: 0 | CD13: 0 | CE13: 0 | CF13: 2 | CG13: 0 | CH13: 102 | CI13: 7 | CJ13: 30 | CK13: 20 | CL13: 2 | CM13: 0 | CN13: 0 | CO13: 0 | CP13: 2 | CQ13: 0 | CS13: 0 | CT13: 6 | CU13: 0 | CV13: 2 | CW13: 6 | CX13: 0 | CY13: 1 | CZ13: 41 | DA13: 12 | DB13: 0 | DC13: 0 | DD13: 0 | DE13: 2 | DF13: 42 | DG13: 0 | DH13: 4 | DI13: 4 | DJ13: 0 | DK13: 0 | DM13: 0 | DN13: 0 | DO13: 0 | DQ13: 34 | DS13: 0 | DT13: 1 | DU13: 0 | DV13: 0 | DX13: 0 | DY13: 0 | DZ13: 0 | EA13: 0 | EB13: 4 | EC13: 0 | ED13: 5 | EE13: 3 | EF13: 17 | EG13: 0 | EH13: 0 | EI13: 0 | EJ13: 0 | EK13: 0 | EM13: 0 | EN13: 209
A14: 30 | B14: 112 | C14: 0 | D14: 1 | E14: 1 | F14: 21 | G14: 0 | H14: 0 | I14: 0 | J14: 0 | K14: 2 | L14: 47 | M14: 39 | N14: 0 | O14: 0 | P14: 0 | Q14: 2 | R14: 0 | S14: 1 | T14: 1 | U14: 0 | V14: 15 | W14: 3 | X14: 0 | Y14: 0 | Z14: 0 | AA14: 0 | AB14: 15 | AC14: 0 | AD14: 4 | AG14: 13 | AH14: 3 | AI14: 22 | AJ14: 0 | AK14: 0 | AL14: 0 | AM14: 0 | AN14: 0 | AO14: 0 | AP14: 0 | AQ14: 1 | AR14: 0 | AS14: 0 | AT14: 0 | AU14: 0 | AV14: 72 | AX14: 1 | AZ14: 11 | BA14: 0 | BB14: 0 | BC14: 0 | BD14: 0 | BE14: 0 | BF14: 0 | BG14: 0 | BH14: 0 | BI14: 0 | BJ14: 0 | BK14: 3 | BL14: 6 | BM14: 0 | BO14: 14 | BP14: 0 | BQ14: 0 | BR14: 0 | BS14: 0 | BT14: 0 | BU14: 0 | BV14: 3 | BW14: 0 | BX14: 0 | BY14: 11 | BZ14: 0 | CA14: 0 | CB14: 4 | CC14: 0 | CD14: 0 | CE14: 0 | CF14: 5 | CG14: 0 | CH14: 104 | CI14: 4 | CJ14: 44 | CK14: 30 | CL14: 5 | CM14: 0 | CN14: 0 | CO14: 0 | CP14: 0 | CQ14: 5 | CS14: 0 | CT14: 7 | CU14: 0 | CV14: 1 | CW14: 6 | CX14: 0 | CY14: 2 | CZ14: 42 | DA14: 14 | DB14: 0 | DC14: 0 | DD14: 0 | DE14: 0 | DF14: 47 | DG14: 0 | DH14: 3 | DI14: 0 | DJ14: 1 | DK14: 0 | DM14: 0 | DN14: 0 | DO14: 0 | DQ14: 19 | DS14: 0 | DT14: 0 | DU14: 1 | DV14: 0 | DX14: 0 | DY14: 0 | DZ14: 0 | EA14: 0 | EB14: 4 | EC14: 0 | ED14: 3 | EE14: 7 | EF14: 14 | EG14: 0 | EH14: 0 | EI14: 0 | EJ14: 0 | EK14: 2 | EM14: 0 | EN14: 211
A15: 34 | B15: 122 | C15: 0 | D15: 0 | E15: 0 | F15: 14 | G15: 0 | H15: 0 | I15: 0 | J15: 0 | K15: 1 | L15: 84 | M15: 36 | N15: 0 | O15: 0 | P15: 0 | Q15: 9 | R15: 0 | S15: 0 | T15: 2 | U15: 0 | V15: 25 | W15: 2 | X15: 0 | Y15: 0 | Z15: 0 | AA15: 0 | AB15: 43 | AC15: 0 | AD15: 7 | AG15: 22 | AH15: 6 | AI15: 25 | AJ15: 0 | AK15: 0 | AL15: 0 | AM15: 0 | AN15: 0 | AO15: 0 | AP15: 0 | AQ15: 2 | AR15: 0 | AS15: 0 | AT15: 0 | AU15: 0 | AV15: 100 | AX15: 4 | AZ15: 9 | BA15: 0 | BB15: 0 | BC15: 0 | BD15: 0 | BE15: 0 | BF15: 0 | BG15: 0 | BH15: 1 | BI15: 0 | BJ15: 0 | BK15: 0 | BL15: 8 | BM15: 0 | BO15: 15 | BP15: 0 | BQ15: 0 | BR15: 1 | BS15: 0 | BT15: 0 | BU15: 0 | BV15: 0 | BW15: 0 | BX15: 0 | BY15: 11 | BZ15: 0 | CA15: 0 | CB15: 4 | CC15: 0 | CD15: 0 | CE15: 0 | CF15: 1 | CG15: 0 | CH15: 230 | CI15: 7 | CJ15: 33 | CK15: 30 | CL15: 8 | CM15: 0 | CN15: 0 | CO15: 0 | CP15: 0 | CQ15: 1 | CS15: 0 | CT15: 9 | CU15: 0 | CV15: 2 | CW15: 9 | CX15: 0 | CY15: 1 | CZ15: 50 | DA15: 10 | DB15: 0 | DC15: 0 | DD15: 0 | DE15: 2 | DF15: 54 | DG15: 0 | DH15: 6 | DI15: 2 | DJ15: 2 | DK15: 0 | DM15: 0 | DN15: 0 | DO15: 0 | DQ15: 63 | DS15: 0 | DT15: 0 | DU15: 0 | DV15: 1 | DX15: 0 | DY15: 0 | DZ15: 0 | EA15: 0 | EB15: 5 | EC15: 0 | ED15: 3 | EE15: 1 | EF15: 18 | EG15: 0 | EH15: 0 | EI15: 0 | EJ15: 0 | EK15: 0 | EM15: 0 | EN15: 299
A16: 38 | B16: 134 | C16: 1 | D16: 0 | E16: 0 | F16: 17 | G16: 0 | H16: 0 | I16: 0 | J16: 0 | K16: 0 | L16: 106 | M16: 28 | N16: 0 | O16: 0 | P16: 0 | Q16: 16 | R16: 0 | S16: 0 | T16: 5 | U16: 0 | V16: 13 | W16: 3 | X16: 0 | Y16: 1 | Z16: 1 | AA16: 0 | AB16: 30 | AC16: 0 | AD16: 5 | AG16: 22 | AH16: 4 | AI16: 19 | AJ16: 0 | AK16: 0 | AL16: 0 | AM16: 0 | AN16: 0 | AO16: 0 | AP16: 0 | AQ16: 2 | AR16: 0 | AS16: 0 | AT16: 0 | AU16: 0 | AV16: 69 | AX16: 1 | AZ16: 7 | BA16: 2 | BB16: 0 | BC16: 0 | BD16: 0 | BE16: 0 | BF16: 0 | BG16: 0 | BH16: 0 | BI16: 0 | BJ16: 0 | BK16: 1 | BL16: 12 | BM16: 0 | BO16: 54 | BP16: 0 | BQ16: 0 | BR16: 0 | BS16: 0 | BT16: 0 | BU16: 0 | BV16: 0 | BW16: 1 | BX16: 0 | BY16: 6 | BZ16: 0 | CA16: 0 | CB16: 6 | CC16: 0 | CD16: 0 | CE16: 0 | CF16: 3 | CG16: 0 | CH16: 143 | CI16: 4 | CJ16: 52 | CK16: 28 | CL16: 2 | CM16: 0 | CN16: 0 | CO16: 0 | CP16: 0 | CQ16: 0 | CS16: 0 | CT16: 16 | CU16: 0 | CV16: 1 | CW16: 6 | CX16: 0 | CY16: 4 | CZ16: 63 | DA16: 7 | DB16: 0 | DC16: 0 | DD16: 0 | DE16: 0 | DF16: 67 | DG16: 0 | DH16: 3 | DI16: 0 | DJ16: 2 | DK16: 0 | DM16: 0 | DN16: 0 | DO16: 0 | DQ16: 101 | DS16: 0 | DT16: 0 | DU16: 0 | DV16: 1 | DX16: 0 | DY16: 0 | DZ16: 1 | EA16: 0 | EB16: 10 | EC16: 0 | ED16: 3 | EE16: 2 | EF16: 9 | EG16: 3 | EH16: 0 | EI16: 0 | EJ16: 0 | EK16: 0 | EM16: 0 | EN16: 352
... A341: 827 | B341: 10580 | C341: 0 | D341: 0 | E341: 0 | F341: 1 | G341: 0 | H341: 0 | I341: 0 | J341: 0 | K341: 6 | L341: 0 | M341: 166 | N341: 0 | O341: 0 | P341: 0 | Q341: 0 | R341: 0 | S341: 0 | T341: 0 | U341: 0 | V341: 0 | W341: 0 | X341: 0 | Y341: 0 | Z341: 0 | AA341: 0 | AB341: 0 | AC341: 0 | AD341: 0 | AG341: 1744 | AH341: 1 | AI341: 14 | AJ341: 0 | AK341: 0 | AL341: 0 | AM341: 0 | AN341: 0 | AO341: 0 | AP341: 0 | AQ341: 0 | AR341: 0 | AS341: 0 | AT341: 0 | AU341: 0 | AV341: 0 | AX341: 8 | AZ341: 0 | BA341: 1 | BB341: 0 | BC341: 0 | BD341: 0 | BE341: 0 | BF341: 0 | BG341: 0 | BH341: 1 | BI341: 0 | BJ341: 0 | BK341: 0 | BL341: 0 | BM341: 0 | BO341: 0 | BP341: 0 | BQ341: 0 | BR341: 0 | BS341: 0 | BT341: 0 | BU341: 0 | BV341: 0 | BW341: 0 | BX341: 0 | BY341: 0 | BZ341: 0 | CA341: 0 | CB341: 0 | CC341: 0 | CD341: 0 | CE341: 0 | CF341: 1 | CG341: 0 | CH341: 0 | CI341: 0 | CJ341: 234 | CK341: 0 | CL341: 0 | CM341: 0 | CN341: 0 | CO341: 0 | CP341: 0 | CQ341: 0 | CS341: 0 | CT341: 28 | CU341: 0 | CV341: 38 | CW341: 8 | CX341: 0 | CY341: 0 | CZ341: 25 | DA341: 0 | DB341: 0 | DC341: 0 | DD341: 0 | DE341: 3 | DF341: 3 | DG341: 0 | DH341: 28 | DI341: 0 | DJ341: 2 | DK341: 0 | DM341: 0 | DN341: 0 | DO341: 0 | DQ341: 0 | DS341: 0 | DT341: 0 | DU341: 4 | DV341: 0 | DX341: 0 | DY341: 4 | DZ341: 0 | EA341: 0 | EB341: 2 | EC341: 1 | ED341: 16 | EE341: 0 | EF341: 3 | EG341: 0 | EH341: 0 | EI341: 0 | EJ341: 0 | EK341: 0 | EM341: 0 | EN341: 38
A342: 829 | B342: 10609 | C342: 0 | D342: 0 | E342: 0 | F342: 0 | G342: 0 | H342: 0 | I342: 0 | J342: 0 | K342: 4 | L342: 0 | M342: 197 | N342: 0 | O342: 0 | P342: 0 | Q342: 0 | R342: 0 | S342: 0 | T342: 0 | U342: 0 | V342: 0 | W342: 0 | X342: 0 | Y342: 0 | Z342: 0 | AA342: 0 | AB342: 0 | AC342: 0 | AD342: 0 | AG342: 1828 | AH342: 0 | AI342: 12 | AJ342: 0 | AK342: 0 | AL342: 0 | AM342: 0 | AN342: 0 | AO342: 0 | AP342: 0 | AQ342: 3 | AR342: 0 | AS342: 0 | AT342: 0 | AU342: 0 | AV342: 0 | AX342: 6 | AZ342: 0 | BA342: 1 | BB342: 0 | BC342: 0 | BD342: 0 | BE342: 0 | BF342: 0 | BG342: 0 | BH342: 3 | BI342: 0 | BJ342: 0 | BK342: 0 | BL342: 0 | BM342: 0 | BO342: 0 | BP342: 0 | BQ342: 0 | BR342: 0 | BS342: 0 | BT342: 0 | BU342: 0 | BV342: 0 | BW342: 0 | BX342: 0 | BY342: 0 | BZ342: 0 | CA342: 0 | CB342: 1 | CC342: 0 | CD342: 0 | CE342: 0 | CF342: 1? | CG342: 0 | CH342: 0 | CI342: 0 | CJ342: 253 | CK342: 0 | CL342: 0 | CM342: 0 | CN342: 0 | CO342: 0 | CP342: 0 | CQ342: 0 | CS342: 0 | CT342: 12 | CU342: 0 | CV342: 84 | CW342: 0 | CX342: 0 | CY342: 0 | CZ342: 29 | DA342: 0 | DB342: 1 | DC342: 0 | DD342: 0 | DE342: 1 | DF342: 2 | DG342: 0 | DH342: 37 | DI342: 0 | DJ342: 0 | DK342: 0 | DM342: 0 | DN342: 0 | DO342: 0 | DQ342: 0 | DS342: 0 | DT342: 0 | DU342: 2 | DV342: 0 | DX342: 0 | DY342: 1 | DZ342: 0 | EA342: 0 | EB342: 2 | EC342: 0 | ED342: 8 | EE342: 2 | EF342: 1 | EG342: 0 | EH342: 0 | EI342: 0 | EJ342: 0 | EK342: 1 | EM342: 0 | EN342: 13
A343: 831 | B343: 10677 | C343: 0 | D343: 0 | E343: 0 | F343: 0 | G343: 0 | H343: 0 | I343: 0 | J343: 0 | K343: 2 | L343: 0 | M343: 336 | N343: 0 | O343: 0 | P343: 0 | Q343: 0 | R343: 0 | S343: 1 | T343: 0 | U343: 0 | V343: 0 | W343: 0 | X343: 0 | Y343: 0 | Z343: 0 | AA343: 0 | AB343: 0 | AC343: 0 | AD343: 0 | AG343: 1671 | AH343: 0 | AI343: 18 | AJ343: 0 | AK343: 0 | AL343: 0 | AM343: 0 | AN343: 0 | AO343: 0 | AP343: 0 | AQ343: 0 | AR343: 0 | AS343: 0 | AT343: 0 | AU343: 0 | AV343: 0 | AX343: 12 | AZ343: 0 | BA343: 1 | BB343: 0 | BC343: 0 | BD343: 0 | BE343: 0 | BF343: 0 | BG343: 0 | BH343: 1 | BI343: 0 | BJ343: 0 | BK343: 0 | BL343: 0 | BM343: 0 | BO343: 0 | BP343: 0 | BQ343: 0 | BR343: 0 | BS343: 0 | BT343: 0 | BU343: 0 | BV343: 0 | BW343: 2 | BX343: 0 | BY343: 0 | BZ343: 0 | CA343: 0 | CB343: 1 | CC343: 0 | CD343: 0 | CE343: 0 | CF343: 0 | CG343: 0 | CH343: 1 | CI343: 0 | CJ343: 426 | CK343: 0 | CL343: 0 | CM343: 1 | CN343: 0 | CO343: 0 | CP343: 0 | CQ343: 0 | CS343: 0 | CT343: 11 | CU343: 0 | CV343: 107 | CW343: 1 | CX343: 0 | CY343: 0 | CZ343: 22 | DA343: 0 | DB343: 0 | DC343: 0 | DD343: 0 | DE343: 2 | DF343: 3 | DG343: 0 | DH343: 24 | DI343: 0 | DJ343: 0 | DK343: 0 | DM343: 0 | DN343: 0 | DO343: 0 | DQ343: 0 | DS343: 0 | DT343: 0 | DU343: 0 | DV343: 0 | DX343: 0 | DY343: 0 | DZ343: 0 | EA343: 0 | EB343: 1 | EC343: 1 | ED343: 13 | EE343: 4 | EF343: 2 | EG343: 0 | EH343: 0 | EI343: 0 | EJ343: 0 | EK343: 0 | EM343: 0 | EN343: 22
A344: 833 | B344: 10712 | C344: 0 | D344: 0 | E344: 0 | F344: 0 | G344: 0 | H344: 0 | I344: 0 | J344: 0 | K344: 2 | L344: 0 | M344: 200 | N344: 0 | O344: 0 | P344: 0 | Q344: 0 | R344: 0 | S344: 0 | T344: 0 | U344: 0 | V344: 0 | W344: 0 | X344: 0 | Y344: 0 | Z344: 0 | AA344: 0 | AB344: 0 | AC344: 0 | AD344: 0 | AG344: 732 | AH344: 1 | AI344: 21 | AJ344: 0 | AK344: 0 | AL344: 0 | AM344: 0 | AN344: 0 | AO344: 0 | AP344: 0 | AQ344: 2 | AR344: 0 | AS344: 0 | AT344: 0 | AU344: 0 | AV344: 0 | AX344: 6 | AZ344: 0 | BA344: 0 | BB344: 0 | BC344: 0 | BD344: 0 | BE344: 0 | BF344: 0 | BG344: 0 | BH344: 1 | BI344: 0 | BJ344: 0 | BK344: 0 | BL344: 0 | BM344: 0 | BO344: 0 | BP344: 0 | BQ344: 0 | BR344: 0 | BS344: 0 | BT344: 0 | BU344: 0 | BV344: 0 | BW344: 0 | BX344: 0 | BY344: 0 | BZ344: 0 | CA344: 0 | CB344: 0 | CC344: 0 | CD344: 0 | CE344: 0 | CF344: 0 | CG344: 0 | CH344: 5 | CI344: 0 | CJ344: 321 | CK344: 0 | CL344: 0 | CM344: 0 | CN344: 0 | CO344: 0 | CP344: 0 | CQ344: 0 | CS344: 0 | CT344: 17 | CU344: 0 | CV344: 46 | CW344: 0 | CX344: 0 | CY344: 0 | CZ344: 11 | DA344: 3 | DB344: 0 | DC344: 0 | DD344: 0 | DE344: 0 | DF344: 2 | DG344: 0 | DH344: 14 | DI344: 0 | DJ344: 0 | DK344: 0 | DM344: 0 | DN344: 1 | DO344: 0 | DQ344: 0 | DS344: 0 | DT344: 0 | DU344: 2 | DV344: 0 | DX344: 0 | DY344: 1 | DZ344: 0 | EA344: 0 | EB344: 0 | EC344: 0 | ED344: 7 | EE344: 2 | EF344: 4 | EG344: 0 | EH344: 0 | EI344: 0 | EJ344: 0 | EK344: 0 | EM344: 0 | EN344: 17
A345: 835 | B345: 10739 | C345: 0 | D345: 0 | E345: 0 | F345: 0 | G345: 0 | H345: 0 | I345: 0 | J345: 0 | K345: 9 | L345: 0 | M345: 499 | N345: 0 | O345: 0 | P345: 0 | Q345: 0 | R345: 0 | S345: 2 | T345: 0 | U345: 0 | V345: 0 | W345: 0 | X345: 0 | Y345: 0 | Z345: 0 | AA345: 1 | AB345: 0 | AC345: 0 | AD345: 0 | AG345: 1085 | AH345: 0 | AI345: 19 | AJ345: 0 | AK345: 0 | AL345: 0 | AM345: 0 | AN345: 0 | AO345: 0 | AP345: 0 | AQ345: 4 | AR345: 0 | AS345: 0 | AT345: 0 | AU345: 0 | AV345: 0 | AX345: 24 | AZ345: 0 | BA345: 2 | BB345: 0 | BC345: 0 | BD345: 0 | BE345: 0 | BF345: 0 | BG345: 0 | BH345: 1 | BI345: 0 | BJ345: 0 | BK345: 0 | BL345: 0 | BM345: 0 | BO345: 2 | BP345: 0 | BQ345: 0 | BR345: 0 | BS345: 0 | BT345: 0 | BU345: 0 | BV345: 0 | BW345: 0 | BX345: 0 | BY345: 0 | BZ345: 0 | CA345: 3 | CB345: 3 | CC345: 0 | CD345: 0 | CE345: 0 | CF345: 0 | CG345: 0 | CH345: 1 | CI345: 0 | CJ345: 325 | CK345: 0 | CL345: 0 | CM345: 0 | CN345: 0 | CO345: 0 | CP345: 0 | CQ345: 0 | CS345: 0 | CT345: 20 | CU345: 0 | CV345: 86 | CW345: 0 | CX345: 0 | CY345: 0 | CZ345: 25 | DA345: 1 | DB345: 0 | DC345: 0 | DD345: 0 | DE345: 0 | DF345: 7 | DG345: 0 | DH345: 22 | DI345: 0 | DJ345: 0 | DK345: 0 | DM345: 0 | DN345: 0 | DO345: 0 | DQ345: 0 | DS345: 0 | DT345: 0 | DU345: 0 | DV345: 0 | DX345: 0 | DY345: 1 | DZ345: 0 | EA345: 0 | EB345: 1 | EC345: 1 | ED345: 11 | EE345: 2 | EF345: 8 | EG345: 0 | EH345: 0 | EI345: 0 | EJ345: 0 | EK345: 2 | EM345: 0 | EN345: 77
A346: 837 | B346: 10763 | C346: 0 | D346: 0 | E346: 0 | F346: 0 | G346: 0 | H346: 0 | I346: 0 | J346: 0 | K346: 11 | L346: 0 | M346: 276 | N346: 0 | O346: 0 | P346: 0 | Q346: 0 | R346: 0 | S346: 0 | T346: 0 | U346: 0 | V346: 0 | W346: 0 | X346: 0 | Y346: 0 | Z346: 0 | AA346: 0 | AB346: 0 | AC346: 0 | AD346: 0 | AG346: 440 | AH346: 1 | AI346: 14 | AJ346: 0 | AK346: 0 | AL346: 0 | AM346: 0 | AN346: 0 | AO346: 0 | AP346: 0 | AQ346: 0 | AR346: 0 | AS346: 0 | AT346: 0 | AU346: 0 | AV346: 0 | AX346: 16 | AZ346: 0 | BA346: 0 | BB346: 0 | BC346: 0 | BD346: 0 | BE346: 0 | BF346: 0 | BG346: 0 | BH346: 2 | BI346: 0 | BJ346: 0 | BK346: 0 | BL346: 0 | BM346: 0 | BO346: 1 | BP346: 0 | BQ346: 0 | BR346: 0 | BS346: 0 | BT346: 0 | BU346: 0 | BV346: 0 | BW346: 0 | BX346: 0 | BY346: 0 | BZ346: 0 | CA346: 1 | CB346: 1 | CC346: 0 | CD346: 0 | CE346: 0 | CF346: 0 | CG346: 0 | CH346: 2 | CI346: 0 | CJ346: 321 | CK346: 0 | CL346: 0 | CM346: 0 | CN346: 0 | CO346: 0 | CP346: 0 | CQ346: 0 | CS346: 0 | CT346: 17 | CU346: 0 | CV346: 51 | CW346: 1 | CX346: 0 | CY346: 0 | CZ346: 12 | DA346: 1 | DB346: 0 | DC346: 0 | DD346: 0 | DE346: 0 | DF346: 1 | DG346: 0 | DH346: 11 | DI346: 0 | DJ346: 2 | DK346: 0 | DM346: 0 | DN346: 0 | DO346: 0 | DQ346: 0 | DS346: 0 | DT346: 0 | DU346: 0 | DV346: 0 | DX346: 0 | DY346: 0 | DZ346: 0 | EA346: 0 | EB346: 1 | EC346: 0 | ED346: 6 | EE346: 3 | EF346: 4 | EG346: 0 | EH346: 0 | EI346: 0 | EJ346: 0 | EK346: 0 | EM346: 0 | EN346: 26
A347: 839 | B347: 10806 | C347: 0 | D347: 0 | E347: 0 | F347: 0 | G347: 0 | H347: 0 | I347: 0 | J347: 0 | K347: 5 | L347: 0 | M347: 481 | N347: 0 | O347: 0 | P347: 0 | Q347: 0 | R347: 0 | S347: 0 | T347: 0 | U347: 0 | V347: 0 | W347: 0 | X347: 0 | Y347: 0 | Z347: 0 | AA347: 0 | AB347: 0 | AC347: 0 | AD347: 0 | AG347: 244 | AH347: 0 | AI347: 20 | AJ347: 0 | AK347: 0 | AL347: 0 | AM347: 0 | AN347: 0 | AO347: 0 | AP347: 0 | AQ347: 0 | AR347: 0 | AS347: 0 | AT347: 0 | AU347: 0 | AV347: 0 | AX347: 15 | AZ347: 0 | BA347: 3 | BB347: 0 | BC347: 0 | BD347: 0 | BE347: 0 | BF347: 0 | BG347: 0 | BH347: 1 | BI347: 0 | BJ347: 0 | BK347: 0 | BL347: 0 | BM347: 0 | BO347: 0 | BP347: 0 | BQ347: 0 | BR347: 0 | BS347: 0 | BT347: 0 | BU347: 0 | BV347: 0 | BW347: 0 | BX347: 0 | BY347: 0 | BZ347: 0 | CA347: 0 | CB347: 5 | CC347: 0 | CD347: 0 | CE347: 0 | CF347: 0 | CG347: 0 | CH347: 5 | CI347: 0 | CJ347: 245 | CK347: 0 | CL347: 0 | CM347: 0 | CN347: 0 | CO347: 0 | CP347: 0 | CQ347: 0 | CS347: 0 | CT347: 9 | CU347: 0 | CV347: 34 | CW347: 0 | CX347: 0 | CY347: 0 | CZ347: 10 | DA347: 0 | DB347: 0 | DC347: 0 | DD347: 0 | DE347: 3 | DF347: 2 | DG347: 0 | DH347: 13 | DI347: 0 | DJ347: 1 | DK347: 0 | DM347: 0 | DN347: 0 | DO347: 0 | DQ347: 0 | DS347: 0 | DT347: 0 | DU347: 0 | DV347: 0 | DX347: 0 | DY347: 0 | DZ347: 0 | EA347: 0 | EB347: 1 | EC347: 0 | ED347: 4 | EE347: 1 | EF347: 8 | EG347: 0 | EH347: 1 | EI347: 0 | EJ347: 0 | EK347: 0 | EM347: 0 | EN347: 36
A348: 841 | B348: 10835 | C348: 0 | D348: 0 | E348: 0 | F348: 0 | G348: 0 | H348: 0 | I348: 0 | J348: 0 | K348: 9 | L348: 0 | M348: 1064 | N348: 0 | O348: 0 | P348: 0 | Q348: 0 | R348: 0 | S348: 1 | T348: 0 | U348: 0 | V348: 0 | W348: 0 | X348: 0 | Y348: 0 | Z348: 0 | AA348: 0 | AB348: 0 | AC348: 0 | AD348: 0 | AG348: 434 | AH348: 0 | AI348: 23 | AJ348: 0 | AK348: 0 | AL348: 0 | AM348: 0 | AN348: 0 | AO348: 0 | AP348: 0 | AQ348: 4 | AR348: 0 | AS348: 0 | AT348: 0 | AU348: 0 | AV348: 0 | AX348: 29 | AZ348: 0 | BA348: 1 | BB348: 0 | BC348: 0 | BD348: 0 | BE348: 0 | BF348: 0 | BG348: 0 | BH348: 1 | BI348: 0 | BJ348: 0 | BK348: 0 | BL348: 0 | BM348: 0 | BO348: 1 | BP348: 0 | BQ348: 0 | BR348: 0 | BS348: 0 | BT348: 0 | BU348: 0 | BV348: 0 | BW348: 0 | BX348: 0 | BY348: 0 | BZ348: 0 | CA348: 5 | CB348: 9 | CC348: 0 | CD348: 0 | CE348: 0 | CF348: 0 | CG348: 0 | CH348: 1 | CI348: 0 | CJ348: 405 | CK348: 0 | CL348: 0 | CM348: 0 | CN348: 0 | CO348: 0 | CP348: 0 | CQ348: 0 | CS348: 0 | CT348: 21 | CU348: 0 | CV348: 72 | CW348: 5 | CX348: 0 | CY348: 0 | CZ348: 19 | DA348: 1 | DB348: 0 | DC348: 0 | DD348: 0 | DE348: 3 | DF348: 7 | DG348: 0 | DH348: 17 | DI348: 0 | DJ348: 1 | DK348: 1 | DM348: 0 | DN348: 0 | DO348: 0 | DQ348: 0 | DS348: 0 | DT348: 0 | DU348: 2 | DV348: 0 | DX348: 0 | DY348: 0 | DZ348: 1 | EA348: 0 | EB348: 7 | EC348: 2 | ED348: 5 | EE348: 4 | EF348: 16 | EG348: 0 | EH348: 0 | EI348: 0 | EJ348: 0 | EK348: 0 | EM348: 0 | EN348: 86
A349: 843 | B349: 10846 | C349: 0 | D349: 0 | E349: 0 | F349: 0 | G349: 0 | H349: 0 | I349: 0 | J349: 0 | K349: 5 | L349: 0 | M349: 554 | N349: 0 | O349: 0 | P349: 0 | Q349: 0 | R349: 0 | S349: 1 | T349: 0 | U349: 0 | V349: 0 | W349: 0 | X349: 0 | Y349: 0 | Z349: 0 | AA349: 0 | AB349: 0 | AC349: 0 | AD349: 1 | AG349: 109 | AH349: 0 | AI349: 17 | AJ349: 0 | AK349: 0 | AL349: 0 | AM349: 0 | AN349: 0 | AO349: 0 | AP349: 0 | AQ349: 3 | AR349: 0 | AS349: 0 | AT349: 0 | AU349: 0 | AV349: 0 | AX349: 14 | AZ349: 0 | BA349: 1 | BB349: 0 | BC349: 0 | BD349: 0 | BE349: 0 | BF349: 0 | BG349: 0 | BH349: 0 | BI349: 0 | BJ349: 0 | BK349: 0 | BL349: 0 | BM349: 0 | BO349: 0 | BP349: 0 | BQ349: 0 | BR349: 0 | BS349: 0 | BT349: 0 | BU349: 0 | BV349: 0 | BW349: 1 | BX349: 0 | BY349: 0 | BZ349: 0 | CA349: 1 | CB349: 2 | CC349: 0 | CD349: 0 | CE349: 0 | CF349: 0 | CG349: 0 | CH349: 0 | CI349: 0 | CJ349: 198 | CK349: 0 | CL349: 0 | CM349: 0 | CN349: 0 | CO349: 0 | CP349: 0 | CQ349: 0 | CS349: 0 | CT349: 13 | CU349: 0 | CV349: 67 | CW349: 3 | CX349: 0 | CY349: 0 | CZ349: 10 | DA349: 0 | DB349: 0 | DC349: 0 | DD349: 0 | DE349: 1 | DF349: 1 | DG349: 0 | DH349: 24 | DI349: 0 | DJ349: 0 | DK349: 0 | DM349: 0 | DN349: 0 | DO349: 0 | DQ349: 0 | DS349: 1 | DT349: 0 | DU349: 1 | DV349: 0 | DX349: 0 | DY349: 0 | DZ349: 0 | EA349: 0 | EB349: 2 | EC349: 0 | ED349: 2 | EE349: 1 | EF349: 7 | EG349: 0 | EH349: 0 | EI349: 0 | EJ349: 0 | EK349: 0 | EM349: 0 | EN349: 37
A350: 845 | B350: 10867 | C350: 0 | D350: 0 | E350: 0 | F350: 0 | G350: 0 | H350: 0 | I350: 0 | J350: 0 | K350: 6 | L350: 0 | M350: 404 | N350: 0 | O350: 0 | P350: 0 | Q350: 0 | R350: 0 | S350: 0 | T350: 0 | U350: 0 | V350: 0 | W350: 0 | X350: 0 | Y350: 0 | Z350: 0 | AA350: 0 | AB350: 0 | AC350: 0 | AD350: 0 | AG350: 48 | AH350: 0 | AI350: 6 | AJ350: 0 | AK350: 0 | AL350: 0 | AM350: 0 | AN350: 0 | AO350: 0 | AP350: 0 | AQ350: 0 | AR350: 0 | AS350: 0 | AT350: 0 | AU350: 0 | AV350: 0 | AX350: 13 | AZ350: 0 | BA350: 1 | BB350: 0 | BC350: 0 | BD350: 0 | BE350: 0 | BF350: 0 | BG350: 0 | BH350: 0 | BI350: 0 | BJ350: 0 | BK350: 0 | BL350: 0 | BM350: 0 | BO350: 0 | BP350: 0 | BQ350: 0 | BR350: 0 | BS350: 0 | BT350: 0 | BU350: 0 | BV350: 0 | BW350: 0 | BX350: 0 | BY350: 0 | BZ350: 0 | CA350: 1 | CB350: 5 | CC350: 0 | CD350: 0 | CE350: 0 | CF350: 0 | CG350: 0 | CH350: 0 | CI350: 0 | CJ350: 321 | CK350: 0 | CL350: 0 | CM350: 0 | CN350: 0 | CO350: 0 | CP350: 0 | CQ350: 0 | CS350: 0 | CT350: 16 | CU350: 0 | CV350: 50 | CW350: 0 | CX350: 0 | CY350: 0 | CZ350: 6 | DA350: 1 | DB350: 0 | DC350: 0 | DD350: 0 | DE350: 0 | DF350: 2 | DG350: 0 | DH350: 11 | DI350: 0 | DJ350: 0 | DK350: 0 | DM350: 0 | DN350: 0 | DO350: 0 | DQ350: 0 | DS350: 0 | DT350: 0 | DU350: 0 | DV350: 0 | DX350: 0 | DY350: 0 | DZ350: 0 | EA350: 0 | EB350: 1 | EC350: 0 | ED350: 3 | EE350: 1 | EF350: 2 | EG350: 0 | EH350: 0 | EI350: 0 | EJ350: 0 | EK350: 0 | EM350: 0 | EN350: 27
A351: 847 | B351: 10899 | C351: 0 | D351: 0 | E351: 0 | F351: 0 | G351: 0 | H351: 0 | I351: 0 | J351: 0 | K351: 5 | L351: 0 | M351: 660 | N351: 0 | O351: 0 | P351: 0 | Q351: 0 | R351: 0 | S351: 1 | T351: 0 | U351: 0 | V351: 0 | W351: 0 | X351: 1 | Y351: 0 | Z351: 0 | AA351: 0 | AB351: 0 | AC351: 0 | AD351: 1 | AG351: 50 | AH351: 0 | AI351: 13 | AJ351: 0 | AK351: 0 | AL351: 0 | AM351: 0 | AN351: 0 | AO351: 0 | AP351: 0 | AQ351: 2 | AR351: 0 | AS351: 0 | AT351: 0 | AU351: 0 | AV351: 0 | AX351: 19 | AZ351: 0 | BA351: 1 | BB351: 0 | BC351: 0 | BD351: 0 | BE351: 0 | BF351: 0 | BG351: 0 | BH351: 0 | BI351: 0 | BJ351: 0 | BK351: 0 | BL351: 2 | BM351: 0 | BO351: 1 | BP351: 0 | BQ351: 0 | BR351: 0 | BS351: 0 | BT351: 0 | BU351: 0 | BV351: 0 | BW351: 0 | BX351: 1 | BY351: 0 | BZ351: 0 | CA351: 0 | CB351: 8 | CC351: 0 | CD351: 0 | CE351: 0 | CF351: 0 | CG351: 0 | CH351: 0 | CI351: 0 | CJ351: 330 | CK351: 0 | CL351: 0 | CM351: 0 | CN351: 0 | CO351: 0 | CP351: 0 | CQ351: 0 | CS351: 0 | CT351: 25 | CU351: 0 | CV351: 58 | CW351: 0 | CX351: 0 | CY351: 0 | CZ351: 1 | DA351: 3 | DB351: 0 | DC351: 0 | DD351: 0 | DE351: 0 | DF351: 3 | DG351: 0 | DH351: 24 | DI351: 0 | DJ351: 1 | DK351: 0 | DM351: 0 | DN351: 0 | DO351: 0 | DQ351: 0 | DS351: 0 | DT351: 0 | DU351: 0 | DV351: 0 | DX351: 0 | DY351: 0 | DZ351: 0 | EA351: 0 | EB351: 2 | EC351: 0 | ED351: 1 | EE351: 9 | EF351: 1 | EG351: 0 | EH351: 0 | EI351: 0 | EJ351: 0 | EK351: 0 | EM351: 0 | EN351: 41
A352: 849 | B352: 10929 | C352: 0 | D352: 0 | E352: 0 | F352: 0 | G352: 0 | H352: 0 | I352: 0 | J352: 0 | K352: 6 | L352: 0 | M352: 586 | N352: 0 | O352: 0 | P352: 0 | Q352: 1 | R352: 0 | S352: 0 | T352: 0 | U352: 0 | V352: 0 | W352: 0 | X352: 0 | Y352: 0 | Z352: 0 | AA352: 0 | AB352: 0 | AC352: 0 | AD352: 0 | AG352: 24 | AH352: 0 | AI352: 12 | AJ352: 0 | AK352: 0 | AL352: 0 | AM352: 0 | AN352: 0 | AO352: 0 | AP352: 0 | AQ352: 1 | AR352: 0 | AS352: 0 | AT352: 0 | AU352: 0 | AV352: 0 | AX352: 15 | AZ352: 0 | BA352: 0 | BB352: 0 | BC352: 0 | BD352: 0 | BE352: 0 | BF352: 0 | BG352: 0 | BH352: 0 | BI352: 0 | BJ352: 0 | BK352: 0 | BL352: 0 | BM352: 0 | BO352: 0 | BP352: 0 | BQ352: 0 | BR352: 0 | BS352: 0 | BT352: 0 | BU352: 0 | BV352: 0 | BW352: 0 | BX352: 0 | BY352: 0 | BZ352: 0 | CA352: 2 | CB352: 1 | CC352: 0 | CD352: 0 | CE352: 0 | CF352: 0 | CG352: 0 | CH352: 0 | CI352: 0 | CJ352: 253 | CK352: 0 | CL352: 0 | CM352: 0 | CN352: 0 | CO352: 0 | CP352: 0 | CQ352: 0 | CS352: 0 | CT352: 18 | CU352: 0 | CV352: 62 | CW352: 0 | CX352: 0 | CY352: 0 | CZ352: 1 | DA352: 1 | DB352: 1 | DC352: 0 | DD352: 0 | DE352: 3 | DF352: 0 | DG352: 0 | DH352: 20 | DI352: 0 | DJ352: 0 | DK352: 0 | DM352: 0 | DN352: 0 | DO352: 0 | DQ352: 0 | DS352: 0 | DT352: 0 | DU352: 0 | DV352: 0 | DX352: 0 | DY352: 1 | DZ352: 0 | EA352: 0 | EB352: 1 | EC352: 0 | ED352: 4 | EE352: 3 | EF352: 7 | EG352: 0 | EH352: 0 | EI352: 0 | EJ352: 0 | EK352: 0 | EM352: 0 | EN352: 35
A353: 851 | B353: 10948 | C353: 0 | D353: 0 | E353: 0 | F353: 0 | G353: 0 | H353: 0 | I353: 0 | J353: 0 | K353: 14 | L353: 1 | M353: 1077 | N353: 0 | O353: 0 | P353: 0 | Q353: 0 | R353: 0 | S353: 1 | T353: 0 | U353: 0 | V353: 0 | W353: 1 | X353: 1 | Y353: 0 | Z353: 0 | AA353: 0 | AB353: 0 | AC353: 0 | AD353: 0 | AG353: 21 | AH353: 0 | AI353: 41 | AJ353: 0 | AK353: 0 | AL353: 0 | AM353: 0 | AN353: 0 | AO353: 0 | AP353: 0 | AQ353: 4 | AR353: 0 | AS353: 0 | AT353: 0 | AU353: 0 | AV353: 0 | AX353: 28 | AZ353: 0 | BA353: 2 | BB353: 0 | BC353: 0 | BD353: 0 | BE353: 0 | BF353: 0 | BG353: 0 | BH353: 1 | BI353: 0 | BJ353: 0 | BK353: 0 | BL353: 1 | BM353: 0 | BO353: 5 | BP353: 0 | BQ353: 0 | BR353: 0 | BS353: 0 | BT353: 0 | BU353: 0 | BV353: 0 | BW353: 0 | BX353: 0 | BY353: 0 | BZ353: 0 | CA353: 5 | CB353: 10 | CC353: 0 | CD353: 0 | CE353: 0 | CF353: 0 | CG353: 0 | CH353: 0 | CI353: 0 | CJ353: 560 | CK353: 0 | CL353: 0 | CM353: 0 | CN353: 0 | CO353: 0 | CP353: 0 | CQ353: 0 | CS353: 0 | CT353: 52 | CU353: 0 | CV353: 117 | CW353: 4 | CX353: 0 | CY353: 0 | CZ353: 9 | DA353: 2 | DB353: 0 | DC353: 0 | DD353: 0 | DE353: 3 | DF353: 4 | DG353: 0 | DH353: 38 | DI353: 0 | DJ353: 2 | DK353: 0 | DM353: 0 | DN353: 0 | DO353: 0 | DQ353: 0 | DS353: 0 | DT353: 0 | DU353: 1 | DV353: 0 | DX353: 0 | DY353: 1 | DZ353: 0 | EA353: 0 | EB353: 2 | EC353: 1 | ED353: 7 | EE353: 6 | EF353: 5 | EG353: 0 | EH353: 1 | EI353: 0 | EJ353: 0 | EK353: 1 | EM353: 0 | EN353: 75
A354: 853 | B354: 10969 | C354: 0 | D354: 0 | E354: 0 | F354: 0 | G354: 0 | H354: 0 | I354: 0 | J354: 0 | K354: 19 | L354: 0 | M354: 926 | N354: 0 | O354: 0 | P354: 0 | Q354: 1 | R354: 0 | S354: 1 | T354: 0 | U354: 0 | V354: 0 | W354: 0 | X354: 0 | Y354: 0 | Z354: 0 | AA354: 0 | AB354: 0 | AC354: 0 | AD354: 0 | AG354: 19 | AH354: 0 | AI354: 48 | AJ354: 0 | AK354: 0 | AL354: 0 | AM354: 0 | AN354: 0 | AO354: 0 | AP354: 0 | AQ354: 1 | AR354: 0 | AS354: 0 | AT354: 0 | AU354: 0 | AV354: 0 | AX354: 53 | AZ354: 0 | BA354: 2 | BB354: 0 | BC354: 0 | BD354: 0 | BE354: 0 | BF354: 0 | BG354: 0 | BH354: 0 | BI354: 0 | BJ354: 0 | BK354: 0 | BL354: 3 | BM354: 0 | BO354: 2 | BP354: 0 | BQ354: 0 | BR354: 0 | BS354: 0 | BT354: 0 | BU354: 0 | BV354: 0 | BW354: 0 | BX354: 0 | BY354: 0 | BZ354: 0 | CA354: 7 | CB354: 3 | CC354: 0 | CD354: 0 | CE354: 0 | CF354: 0 | CG354: 0 | CH354: 2 | CI354: 0 | CJ354: 573 | CK354: 0 | CL354: 0 | CM354: 0 | CN354: 0 | CO354: 0 | CP354: 0 | CQ354: 0 | CS354: 0 | CT354: 61 | CU354: 0 | CV354: 115 | CW354: 0 | CX354: 0 | CY354: 0 | CZ354: 4 | DA354: 0 | DB354: 0 | DC354: 0 | DD354: 0 | DE354: 0 | DF354: 7 | DG354: 0 | DH354: 61 | DI354: 0 | DJ354: 1 | DK354: 0 | DM354: 0 | DN354: 0 | DO354: 0 | DQ354: 0 | DS354: 0 | DT354: 0 | DU354: 0 | DV354: 1 | DX354: 0 | DY354: 1 | DZ354: 0 | EA354: 0 | EB354: 0 | EC354: 0 | ED354: 4 | EE354: 6 | EF354: 14 | EG354: 0 | EH354: 0 | EI354: 0 | EJ354: 0 | EK354: 0 | EM354: 0 | EN354: 121
... A404: 953 | B404: 13045 | C404: 0 | D404: 0 | E404: 0 | F404: 0 | G404: 0 | H404: 0 | I404: 0 | J404: 0 | K404: 24 | L404: 0 | M404: 178 | N404: 0 | O404: 0 | P404: 0 | Q404: 0 | R404: 0 | S404: 2 | T404: 0 | U404: 0 | V404: 0 | W404: 0 | X404: 0 | Y404: 0 | Z404: 0 | AA404: 0 | AB404: 0 | AC404: 0 | AD404: 0 | AG404: 0 | AH404: 0 | AI404: 34 | AJ404: 0 | AK404: 0 | AL404: 0 | AM404: 0 | AN404: 0 | AO404: 0 | AP404: 0 | AQ404: 1 | AR404: 0 | AS404: 0 | AT404: 0 | AU404: 0 | AV404: 0 | AX404: 35 | AZ404: 0 | BA404: 7 | BB404: 0 | BC404: 0 | BD404: 0 | BE404: 0 | BF404: 1 | BG404: 0 | BH404: 0 | BI404: 0 | BJ404: 0 | BK404: 0 | BL404: 2 | BM404: 0 | BO404: 0 | BP404: 0 | BQ404: 0 | BR404: 0 | BS404: 0 | BT404: 0 | BU404: 0 | BV404: 0 | BW404: 0 | BX404: 0 | BY404: 0 | BZ404: 0 | CA404: 0 | CB404: 1 | CC404: 0 | CD404: 0 | CE404: 0 | CF404: 0 | CG404: 0 | CH404: 33 | CI404: 0 | CJ404: 73 | CK404: 0 | CL404: 1 | CM404: 0 | CN404: 0 | CO404: 0 | CP404: 0 | CQ404: 0 | CS404: 0 | CT404: 2 | CU404: 0 | CV404: 5 | CW404: 3 | CX404: 0 | CY404: 0 | CZ404: 0 | DA404: 0 | DB404: 0 | DC404: 0 | DD404: 0 | DE404: 1 | DF404: 1 | DG404: 0 | DH404: 25 | DI404: 0 | DJ404: 0 | DK404: 0 | DM404: 0 | DN404: 0 | DO404: 0 | DQ404: 0 | DS404: 0 | DT404: 0 | DU404: 0 | DV404: 0 | DX404: 0 | DY404: 4 | DZ404: 0 | EA404: 0 | EB404: 2 | EC404: 0 | ED404: 0 | EE404: 11 | EF404: 16 | EG404: 0 | EH404: 0 | EI404: 0 | EJ404: 0 | EK404: 0 | EM404: 0 | EN404: 214
A405: =[2]forR!$B5/10 -> 1187.3 | B405: 13258 | C405: 0 | F405: 0 | J405: 0 | K405: 2.210884 | M405: 26.36054 | O405: 0 | Q405: 0 | S405: 0.3401361 | V405: 0 | W405: 0.170068 | AA405: 0 | AD405: 0.170068 | AE405: 0.8503401 | AF405: 0.170068 | AG405: 0 | AH405: 0 | AI405: 7.823129 | AL405: 0 | AN405: 0 | AP405: 0 | AQ405: 0 | AR405: 0 | AV405: 0 | AW405: 0 | AX405: 3.571429 | AY405: 0 | BA405: 1.020408 | BB405: 0 | BC405: 0 | BF405: 0 | BG405: 0.170068 | BI405: 0 | BL405: 0.3401361 | BM405: 0 | BN405: 0.170068 | BV405: 0 | BW405: 0 | BX405: 0 | CB405: 1 | CH405: 43 | CI405: 0 | CJ405: 24.14966 | CK405: 0 | CL405: 0 | CN405: 0 | CQ405: 0 | CR405: 0 | CV405: 0.170068 | CW405: 0 | CX405: 0 | CZ405: 0 | DA405: 0.5102041 | DE405: 0 | DF405: 1.020408 | DH405: 1.70068 | DJ405: 0 | DL405: 0 | DN405: 0 | DO405: 0 | DP405: 0 | DR405: 0 | DU405: 0 | DV405: 0 | DW405: 0 | DY405: 0.5102041 | DZ405: 0 | ED405: 0 | EE405: 1.870748 | EF405: 0 | EG405: 0 | EJ405: 0.170068 | EL405: 0 | EN405: 26.53061
A406: =[2]forR!$B6/10 -> 1189.5 | B406: 13289 | C406: 0 | F406: 0 | J406: 0 | K406: 5.710491 | M406: 29.08367 | O406: 1 | Q406: 0 | S406: 0 | V406: 0 | W406: 0 | AA406: 0 | AD406: 0.1328021 | AE406: 0.3984064 | AF406: 0.1328021 | AG406: 0 | AH406: 0 | AI406: 4.780877 | AL406: 0 | AN406: 0 | AP406: 0 | AQ406: 0 | AR406: 0 | AV406: 0 | AW406: 0 | AX406: 6.2417 | AY406: 0 | BA406: 1.460823 | BB406: 0 | BC406: 0.1328021 | BF406: 0 | BG406: 0 | BI406: 0 | BL406: 0.3984064 | BM406: 0 | BN406: 0.3984064 | BV406: 0 | BW406: 0 | BX406: 0 | CB406: 3 | CH406: 59 | CI406: 0.1328021 | CJ406: 22.84196 | CK406: 0 | CL406: 0.1328021 | CN406: 0 | CQ406: 0 | CR406: 0 | CV406: 0.2656043 | CW406: 2 | CX406: 0.1328021 | CZ406: 0 | DA406: 0.7968128 | DE406: 0.1328021 | DF406: 1.328021 | DH406: 2.52324 | DJ406: 0.1328021 | DL406: 0.1328021 | DN406: 0 | DO406: 0 | DP406: 0 | DR406: 0 | DU406: 0 | DV406: 0 | DW406: 0 | DY406: 0.9296149 | DZ406: 0 | ED406: 0 | EE406: 1.593626 | EF406: 0 | EG406: 0.1328021 | EJ406: 0 | EL406: 0 | EN406: 19.92032
A407: =[2]forR!$B7/10 -> 1191.7 | B407: 13320 | C407: 0 | F407: 0 | J407: 0 | K407: 3.809524 | M407: 32.10884 | O407: 0 | Q407: 0 | S407: 0.5442177 | V407: 0 | W407: 0 | AA407: 0.1360544 | AD407: 0 | AE407: 0.2721089 | AF407: 0.5442177 | AG407: 0 | AH407: 0 | AI407: 7.755102 | AL407: 0 | AN407: 0 | AP407: 0.1360544 | AQ407: 2 | AR407: 0 | AV407: 0 | AW407: 0 | AX407: 3.129252 | AY407: 0 | BA407: 0.4081633 | BB407: 0 | BC407: 0.1360544 | BF407: 0 | BG407: 0 | BI407: 0 | BL407: 0.2721089 | BM407: 0 | BN407: 0 | BV407: 0 | BW407: 0.1360544 | BX407: 0 | CB407: 9 | CH407: 72 | CI407: 0 | CJ407: 22.72109 | CK407: 0 | CL407: 0 | CN407: 0 | CQ407: 0 | CR407: 0 | CV407: 0 | CW407: 5 | CX407: 0.1360544 | CZ407: 0 | DA407: 1.632653 | DE407: 0 | DF407: 0.2721089 | DH407: 3.129252 | DJ407: 0.1360544 | DL407: 0 | DN407: 0 | DO407: 0 | DP407: 0 | DR407: 0 | DU407: 0 | DV407: 2 | DW407: 0 | DY407: 0.6802721 | DZ407: 0 | ED407: 0 | EE407: 1.496599 | EF407: 0 | EG407: 0 | EJ407: 0 | EL407: 0 | EN407: 20.40816
A408: =[2]forR!$B8/10 -> 1193.8 | B408: 13350 | C408: 0 | F408: 0 | J408: 0 | K408: 2.140673 | M408: 27.21712 | O408: 0 | Q408: 0 | S408: 0.4587156 | V408: 0 | W408: 0.1529052 | AA408: 0 | AD408: 0 | AE408: 0.764526 | AF408: 0.1529052 | AG408: 0 | AH408: 0 | AI408: 10.39755 | AL408: 0 | AN408: 0.1529052 | AP408: 0 | AQ408: 5 | AR408: 0 | AV408: 0 | AW408: 0 | AX408: 3.82263 | AY408: 0 | BA408: 0.4587156 | BB408: 0 | BC408: 0 | BF408: 0.3058104 | BG408: 0 | BI408: 0 | BL408: 0 | BM408: 0 | BN408: 0 | BV408: 0 | BW408: 0 | BX408: 0 | CB408: 11 | CH408: 57 | CI408: 0 | CJ408: 16.05505 | CK408: 0 | CL408: 0 | CN408: 0 | CQ408: 0 | CR408: 0 | CV408: 0.1529052 | CW408: 5 | CX408: 0.1529052 | CZ408: 0 | DA408: 1.070336 | DE408: 0.1529052 | DF408: 0.4587156 | DH408: 2.140673 | DJ408: 0.1529052 | DL408: 0 | DN408: 0 | DO408: 0 | DP408: 0 | DR408: 0 | DU408: 0 | DV408: 0 | DW408: 0 | DY408: 0.6116208 | DZ408: 0 | ED408: 0 | EE408: 2.140673 | EF408: 0.1529052 | EG408: 0 | EJ408: 0.1529052 | EL408: 0 | EN408: 30.58104
A409: =[2]forR!$B9/10 -> 1196 | B409: 13382 | C409: 0 | F409: 0 | J409: 0 | K409: 4.926108 | M409: 43.84237 | O409: 0 | Q409: 0 | S409: 0.3284072 | V409: 0 | W409: 0 | AA409: 0 | AD409: 0.1642036 | AE409: 0.3284072 | AF409: 0.4926108 | AG409: 0 | AH409: 0 | AI409: 5.090312 | AL409: 0 | AN409: 0 | AP409: 0 | AQ409: 0 | AR409: 0 | AV409: 0 | AW409: 0 | AX409: 4.926108 | AY409: 0 | BA409: 0.3284072 | BB409: 0 | BC409: 0 | BF409: 0 | BG409: 0 | BI409: 0 | BL409: 0.1642036 | BM409: 0 | BN409: 0 | BV409: 0 | BW409: 0 | BX409: 0 | CB409: 13 | CH409: 54 | CI409: 0 | CJ409: 15.76355 | CK409: 0 | CL409: 0 | CN409: 0 | CQ409: 0 | CR409: 0 | CV409: 0.4926108 | CW409: 2 | CX409: 0 | CZ409: 0 | DA409: 0.821018 | DE409: 0 | DF409: 0.4926108 | DH409: 3.940887 | DJ409: 0 | DL409: 0 | DN409: 0 | DO409: 0 | DP409: 0 | DR409: 0 | DU409: 0 | DV409: 0 | DW409: 0 | DY409: 0.4926108 | DZ409: 0 | ED409: 0 | EE409: 2.134647 | EF409: 0 | EG409: 0 | EJ409: 0 | EL409: 0 | EN409: 15.27094
A410: =[2]forR!$B10/10 -> 1198.2 | B410: 13413 | C410: 0 | F410: 0 | J410: 0 | K410: 5.007587 | M410: 39.60546 | O410: 2 | Q410: 0 | S410: 0.1517451 | V410: 0.1517451 | W410: 0.1517451 | AA410: 0.3034901 | AD410: 0 | AE410: 0.7587253 | AF410: 0 | AG410: 0 | AH410: 0 | AI410: 7.738998 | AL410: 0 | AN410: 0 | AP410: 0 | AQ410: 0 | AR410: 0 | AV410: 0 | AW410: 0 | AX410: 2.883156 | AY410: 0 | BA410: 0.6069803 | BB410: 0 | BC410: 0 | BF410: 0.1517451 | BG410: 0 | BI410: 0 | BL410: 0.1517451 | BM410: 0 | BN410: 0 | BV410: 0 | BW410: 0 | BX410: 0 | CB410: 9 | CH410: 51 | CI410: 0 | CJ410: 16.08498 | CK410: 0 | CL410: 0.1517451 | CN410: 0 | CQ410: 0 | CR410: 0 | CV410: 0.7587253 | CW410: 3 | CX410: 0 | CZ410: 0.1517451 | DA410: 1.669196 | DE410: 0.1517451 | DF410: 0.1517451 | DH410: 4.097117 | DJ410: 0.1517451 | DL410: 0 | DN410: 0 | DO410: 0 | DP410: 0 | DR410: 0 | DU410: 0 | DV410: 1 | DW410: 0 | DY410: 0.3034901 | DZ410: 0 | ED410: 0 | EE410: 2.124431 | EF410: 0 | EG410: 0 | EJ410: 0 | EL410: 0 | EN410: 16.54021
A411: =[2]forR!$B11/10 -> 1200.5 | B411: 13446 | C411: 0 | F411: 0 | J411: 0 | K411: 3.453689 | M411: 49.76452 | O411: 1 | Q411: 0 | S411: 0.1569859 | V411: 0 | W411: 0 | AA411: 0 | AD411: 0 | AE411: 0.3139717 | AF411: 0.1569859 | AG411: 0 | AH411: 0 | AI411: 3.453689 | AL411: 0 | AN411: 0 | AP411: 0 | AQ411: 0 | AR411: 0 | AV411: 0 | AW411: 0 | AX411: 2.982732 | AY411: 0 | BA411: 0.1569859 | BB411: 0 | BC411: 0 | BF411: 0 | BG411: 0 | BI411: 0 | BL411: 0.6279435 | BM411: 0 | BN411: 0 | BV411: 0 | BW411: 0 | BX411: 0 | CB411: 3 | CH411: 54 | CI411: 0 | CJ411: 14.59969 | CK411: 0 | CL411: 0 | CN411: 0 | CQ411: 0 | CR411: 0 | CV411: 0.9419152 | CW411: 5 | CX411: 0 | CZ411: 0.1569859 | DA411: 0.9419152 | DE411: 0 | DF411: 1.098901 | DH411: 3.924647 | DJ411: 0 | DL411: 0 | DN411: 0 | DO411: 0 | DP411: 0 | DR411: 0 | DU411: 0 | DV411: 0 | DW411: 0 | DY411: 0.4709576 | DZ411: 0 | ED411: 0 | EE411: 2.354788 | EF411: 0 | EG411: 0 | EJ411: 0 | EL411: 0 | EN411: 14.4427
A412: =[2]forR!$B12/10 -> 1202.5 | B412: 13473 | C412: 0 | F412: 0 | J412: 0 | K412: 2.711324 | M412: 43.22169 | O412: 0 | Q412: 0 | S412: 0.3189793 | V412: 0 | W412: 0.1594896 | AA412: 0 | AD412: 0 | AE412: 0.6379585 | AF412: 0 | AG412: 0 | AH412: 0 | AI412: 6.698565 | AL412: 0 | AN412: 0 | AP412: 0 | AQ412: 0 | AR412: 0 | AV412: 0 | AW412: 0 | AX412: 4.14673 | AY412: 0 | BA412: 0.4784689 | BB412: 0 | BC412: 0 | BF412: 0.4784689 | BG412: 0 | BI412: 0 | BL412: 0.4784689 | BM412: 0 | BN412: 0 | BV412: 0 | BW412: 0 | BX412: 0 | CB412: 4 | CH412: 69 | CI412: 0 | CJ412: 16.58692 | CK412: 0 | CL412: 0 | CN412: 0 | CQ412: 0 | CR412: 0 | CV412: 1.275917 | CW412: 1 | CX412: 0.1594896 | CZ412: 0.3189793 | DA412: 1.594896 | DE412: 0 | DF412: 0 | DH412: 4.46571 | DJ412: 0 | DL412: 0 | DN412: 0 | DO412: 0 | DP412: 0 | DR412: 0 | DU412: 0 | DV412: 0 | DW412: 0 | DY412: 0.6379585 | DZ412: 0 | ED412: 0 | EE412: 0.7974482 | EF412: 0 | EG412: 0 | EJ412: 0 | EL412: 0 | EN412: 14.83254
A413: =[2]forR!$B13/10 -> 1204.8 | B413: 13503 | C413: 0 | F413: 0 | J413: 0 | K413: 3.859649 | M413: 44.21053 | O413: 1 | Q413: 0 | S413: 0.7017544 | V413: 0 | W413: 0 | AA413: 0 | AD413: 0 | AE413: 0.7017544 | AF413: 0 | AG413: 0 | AH413: 0 | AI413: 6.842105 | AL413: 0 | AN413: 0 | AP413: 0.1754386 | AQ413: 0 | AR413: 0 | AV413: 0 | AW413: 0 | AX413: 2.105263 | AY413: 0 | BA413: 0.7017544 | BB413: 0 | BC413: 0 | BF413: 0.1754386 | BG413: 0 | BI413: 0 | BL413: 0.877193 | BM413: 0 | BN413: 0 | BV413: 0 | BW413: 0 | BX413: 0 | CB413: 1 | CH413: 25 | CI413: 0 | CJ413: 13.68421 | CK413: 0 | CL413: 0.1754386 | CN413: 0 | CQ413: 0 | CR413: 0 | CV413: 1.052632 | CW413: 5 | CX413: 0 | CZ413: 0 | DA413: 0.5263158 | DE413: 0 | DF413: 0.5263158 | DH413: 5.789474 | DJ413: 0 | DL413: 0 | DN413: 0 | DO413: 0 | DP413: 0 | DR413: 0 | DU413: 0 | DV413: 1 | DW413: 0 | DY413: 0.3508772 | DZ413: 0 | ED413: 0 | EE413: 0.1754386 | EF413: 0 | EG413: 0 | EJ413: 0 | EL413: 0 | EN413: 17.36842
...

Sheet LittLittStacked
